Workbook

Sheet 1. Halbjahr
A1: Kl.: | C1: Fach: | I1: Lehrer/in: | M1: Stand: | N1: =TODAY() -> 46296
B2: FOS/BOS Kempten | C2: 1. Halbjahr
C3: KA | D3: KA | E3: Ex | F3: Ex | G3: Ex | H3: mü | I3: mü | J3: mü | K3: Ø | L3: SA | M3: SA | N3: HJ | O3: HJZ
A4: 1 | C4: =I1KA!C4 | D4: =I2KA!C4 | E4: =I1Ext!C4 | F4: =I2Ext!C4 | G4: =I3Ext!C4 | K4: =IF(COUNT(C4:J4)>0,SUMPRODUCT((C4:J4<>"")*1,C4:J4,$C$39:$J$39)/SUMPRODUCT((C4:J4<>"")*1,$C$39:$J$39),"") | L4: =I1SA!C4 | M4: =I2SA!C4 | N4: =IF(COUNT(K4:M4)>0,AVERAGEIF(K4:M4,"<>"""),"") | O4: =IF(N4<>"",IF(N4<1,0,ROUND(N4,0)),"")
A5: 2 | C5: =I1KA!C5 | D5: =I2KA!C5 | E5: =I1Ext!C5 | F5: =I2Ext!C5 | G5: =I3Ext!C5 | K5: =IF(COUNT(C5:J5)>0,SUMPRODUCT((C5:J5<>"")*1,C5:J5,$C$39:$J$39)/SUMPRODUCT((C5:J5<>"")*1,$C$39:$J$39),"") | L5: =I1SA!C5 | M5: =I2SA!C5 | N5: =IF(COUNT(K5:M5)>0,AVERAGEIF(K5:M5,"<>"""),"") | O5: =IF(N5<>"",IF(N5<1,0,ROUND(N5,0)),"")
A6: 3 | C6: =I1KA!C6 | D6: =I2KA!C6 | E6: =I1Ext!C6 | F6: =I2Ext!C6 | G6: =I3Ext!C6 | K6: =IF(COUNT(C6:J6)>0,SUMPRODUCT((C6:J6<>"")*1,C6:J6,$C$39:$J$39)/SUMPRODUCT((C6:J6<>"")*1,$C$39:$J$39),"") | L6: =I1SA!C6 | M6: =I2SA!C6 | N6: =IF(COUNT(K6:M6)>0,AVERAGEIF(K6:M6,"<>"""),"") | O6: =IF(N6<>"",IF(N6<1,0,ROUND(N6,0)),"")
A7: 4 | C7: =I1KA!C7 | D7: =I2KA!C7 | E7: =I1Ext!C7 | F7: =I2Ext!C7 | G7: =I3Ext!C7 | K7: =IF(COUNT(C7:J7)>0,SUMPRODUCT((C7:J7<>"")*1,C7:J7,$C$39:$J$39)/SUMPRODUCT((C7:J7<>"")*1,$C$39:$J$39),"") | L7: =I1SA!C7 | M7: =I2SA!C7 | N7: =IF(COUNT(K7:M7)>0,AVERAGEIF(K7:M7,"<>"""),"") | O7: =IF(N7<>"",IF(N7<1,0,ROUND(N7,0)),"")
A8: 5 | C8: =I1KA!C8 | D8: =I2KA!C8 | E8: =I1Ext!C8 | F8: =I2Ext!C8 | G8: =I3Ext!C8 | K8: =IF(COUNT(C8:J8)>0,SUMPRODUCT((C8:J8<>"")*1,C8:J8,$C$39:$J$39)/SUMPRODUCT((C8:J8<>"")*1,$C$39:$J$39),"") | L8: =I1SA!C8 | M8: =I2SA!C8 | N8: =IF(COUNT(K8:M8)>0,AVERAGEIF(K8:M8,"<>"""),"") | O8: =IF(N8<>"",IF(N8<1,0,ROUND(N8,0)),"")
A9: 6 | C9: =I1KA!C9 | D9: =I2KA!C9 | E9: =I1Ext!C9 | F9: =I2Ext!C9 | G9: =I3Ext!C9 | K9: =IF(COUNT(C9:J9)>0,SUMPRODUCT((C9:J9<>"")*1,C9:J9,$C$39:$J$39)/SUMPRODUCT((C9:J9<>"")*1,$C$39:$J$39),"") | L9: =I1SA!C9 | M9: =I2SA!C9 | N9: =IF(COUNT(K9:M9)>0,AVERAGEIF(K9:M9,"<>"""),"") | O9: =IF(N9<>"",IF(N9<1,0,ROUND(N9,0)),"")
A10: 7 | C10: =I1KA!C10 | D10: =I2KA!C10 | E10: =I1Ext!C10 | F10: =I2Ext!C10 | G10: =I3Ext!C10 | K10: =IF(COUNT(C10:J10)>0,SUMPRODUCT((C10:J10<>"")*1,C10:J10,$C$39:$J$39)/SUMPRODUCT((C10:J10<>"")*1,$C$39:$J$39),"") | L10: =I1SA!C10 | M10: =I2SA!C10 | N10: =IF(COUNT(K10:M10)>0,AVERAGEIF(K10:M10,"<>"""),"") | O10: =IF(N10<>"",IF(N10<1,0,ROUND(N10,0)),"")
A11: 8 | C11: =I1KA!C11 | D11: =I2KA!C11 | E11: =I1Ext!C11 | F11: =I2Ext!C11 | G11: =I3Ext!C11 | K11: =IF(COUNT(C11:J11)>0,SUMPRODUCT((C11:J11<>"")*1,C11:J11,$C$39:$J$39)/SUMPRODUCT((C11:J11<>"")*1,$C$39:$J$39),"") | L11: =I1SA!C11 | M11: =I2SA!C11 | N11: =IF(COUNT(K11:M11)>0,AVERAGEIF(K11:M11,"<>"""),"") | O11: =IF(N11<>"",IF(N11<1,0,ROUND(N11,0)),"")
A12: 9 | C12: =I1KA!C12 | D12: =I2KA!C12 | E12: =I1Ext!C12 | F12: =I2Ext!C12 | G12: =I3Ext!C12 | K12: =IF(COUNT(C12:J12)>0,SUMPRODUCT((C12:J12<>"")*1,C12:J12,$C$39:$J$39)/SUMPRODUCT((C12:J12<>"")*1,$C$39:$J$39),"") | L12: =I1SA!C12 | M12: =I2SA!C12 | N12: =IF(COUNT(K12:M12)>0,AVERAGEIF(K12:M12,"<>"""),"") | O12: =IF(N12<>"",IF(N12<1,0,ROUND(N12,0)),"")
A13: 10 | C13: =I1KA!C13 | D13: =I2KA!C13 | E13: =I1Ext!C13 | F13: =I2Ext!C13 | G13: =I3Ext!C13 | K13: =IF(COUNT(C13:J13)>0,SUMPRODUCT((C13:J13<>"")*1,C13:J13,$C$39:$J$39)/SUMPRODUCT((C13:J13<>"")*1,$C$39:$J$39),"") | L13: =I1SA!C13 | M13: =I2SA!C13 | N13: =IF(COUNT(K13:M13)>0,AVERAGEIF(K13:M13,"<>"""),"") | O13: =IF(N13<>"",IF(N13<1,0,ROUND(N13,0)),"")
A14: 11 | C14: =I1KA!C14 | D14: =I2KA!C14 | E14: =I1Ext!C14 | F14: =I2Ext!C14 | G14: =I3Ext!C14 | K14: =IF(COUNT(C14:J14)>0,SUMPRODUCT((C14:J14<>"")*1,C14:J14,$C$39:$J$39)/SUMPRODUCT((C14:J14<>"")*1,$C$39:$J$39),"") | L14: =I1SA!C14 | M14: =I2SA!C14 | N14: =IF(COUNT(K14:M14)>0,AVERAGEIF(K14:M14,"<>"""),"") | O14: =IF(N14<>"",IF(N14<1,0,ROUND(N14,0)),"")
A15: 12 | C15: =I1KA!C15 | D15: =I2KA!C15 | E15: =I1Ext!C15 | F15: =I2Ext!C15 | G15: =I3Ext!C15 | K15: =IF(COUNT(C15:J15)>0,SUMPRODUCT((C15:J15<>"")*1,C15:J15,$C$39:$J$39)/SUMPRODUCT((C15:J15<>"")*1,$C$39:$J$39),"") | L15: =I1SA!C15 | M15: =I2SA!C15 | N15: =IF(COUNT(K15:M15)>0,AVERAGEIF(K15:M15,"<>"""),"") | O15: =IF(N15<>"",IF(N15<1,0,ROUND(N15,0)),"")
... A38: 35 | C38: =I1KA!C38 | D38: =I2KA!C38 | E38: =I1Ext!C38 | F38: =I2Ext!C38 | G38: =I3Ext!C38 | K38: =IF(COUNT(C38:J38)>0,SUMPRODUCT((C38:J38<>"")*1,C38:J38,$C$39:$J$39)/SUMPRODUCT((C38:J38<>"")*1,$C$39:$J$39),"") | L38: =I1SA!C38 | M38: =I2SA!C38 | N38: =IF(COUNT(K38:M38)>0,AVERAGEIF(K38:M38,"<>"""),"") | O38: =IF(N38<>"",IF(N38<1,0,ROUND(N38,0)),"")
B39: Gewichte | C39: 2 | D39: 2 | E39: 1 | F39: 1 | G39: 1 | H39: 1 | I39: 1 | J39: 1

Sheet I1SA
B1: I - 1. Schulaufgabe aus | C1: =IF('1. Halbjahr'!E1="","",'1. Halbjahr'!E1) | F1: Datum:
B2: Klasse: | C2: =IF('1. Halbjahr'!B1="","",'1. Halbjahr'!B1) | F2: Lehrer/-in: | G2: =IF('1. Halbjahr'!K1="","",'1. Halbjahr'!K1)
A3: Nr | B3: Name | C3: Punkte | D3: =IF(H3="BE",H3,"") -> BE | E3: NT | G3: Eingabe über: | H3: BE | M3: Prozentsatz erreicht | O3: Notenschluessel | Q3: modifiziert
A4: 1 | B4: =IF('1. Halbjahr'!B4<>"", '1. Halbjahr'!B4, "") | C4: =IF(D4="","",IF($H$3="BE", INDIRECT("P"&MATCH(M4-0.001,$Q$4:$Q$20,-1)+4),D4)) | J4: =+B4&D4 | M4: =IF(D4="","",IF($H$3="BE",100 * D4 / IF(E4="",$H$30,E4))) | O4: =IF($H$32="M", $H$35+12*(100-$H$35)/12, $H$35+30*(100-$H$35)/30) -> 100 | Q4: 100
A5: 2 | B5: =IF('1. Halbjahr'!B5<>"", '1. Halbjahr'!B5, "") | C5: =IF(D5="","",IF($H$3="BE", INDIRECT("P"&MATCH(M5-0.001,$Q$4:$Q$20,-1)+4),D5)) | F5: Auswertung | J5: =+B5&D5 | M5: =IF(D5="","",IF($H$3="BE",100 * D5 / IF(E5="",$H$30,E5))) | O5: =IF($H$32="M", $H$35+11*(100-$H$35)/12, $H$35+27*(100-$H$35)/30) -> 95 | P5: 15 | Q5: =(O5-100*SUM($A$43:A43)/$H$30) -> 95
A6: 3 | B6: =IF('1. Halbjahr'!B6<>"", '1. Halbjahr'!B6, "") | C6: =IF(D6="","",IF($H$3="BE", INDIRECT("P"&MATCH(M6-0.001,$Q$4:$Q$20,-1)+4),D6)) | F6: Punkte | G6: Anzahl | H6: Anteil | J6: =+B6&D6 | M6: =IF(D6="","",IF($H$3="BE",100 * D6 / IF(E6="",$H$30,E6))) | O6: =IF($H$32="M", $H$35+10*(100-$H$35)/12, $H$35+24*(100-$H$35)/30) -> 90 | P6: 14 | Q6: =(O6-100*SUM($A$43:A44)/$H$30) -> 90
A7: 4 | B7: =IF('1. Halbjahr'!B7<>"", '1. Halbjahr'!B7, "") | C7: =IF(D7="","",IF($H$3="BE", INDIRECT("P"&MATCH(M7-0.001,$Q$4:$Q$20,-1)+4),D7)) | F7: 15 | G7: =IF(G$25="","",COUNTIF(C$4:C$38,F7)) -> 0 | H7: =IF(G$25="","",G7/G$25) -> #DIV/0! | J7: =+B7&D7 | M7: =IF(D7="","",IF($H$3="BE",100 * D7 / IF(E7="",$H$30,E7))) | O7: =IF($H$32="M", $H$35+9*(100-$H$35)/12, $H$35+21*(100-$H$35)/30) -> 85 | P7: 13 | Q7: =(O7-100*SUM($A$43:A45)/$H$30) -> 85
A8: 5 | B8: =IF('1. Halbjahr'!B8<>"", '1. Halbjahr'!B8, "") | C8: =IF(D8="","",IF($H$3="BE", INDIRECT("P"&MATCH(M8-0.001,$Q$4:$Q$20,-1)+4),D8)) | F8: 14 | G8: =IF(G$25="","",COUNTIF(C$4:C$38,F8)) -> 0 | H8: =IF(G$25="","",G8/G$25) -> #DIV/0! | I8: =+H7+H8+H9 -> #DIV/0! | J8: =+B8&D8 | M8: =IF(D8="","",IF($H$3="BE",100 * D8 / IF(E8="",$H$30,E8))) | O8: =IF($H$32="M", $H$35+8*(100-$H$35)/12, $H$35+18*(100-$H$35)/30) -> 80 | P8: 12 | Q8: =(O8-100*SUM($A$43:A46)/$H$30) -> 80
A9: 6 | B9: =IF('1. Halbjahr'!B9<>"", '1. Halbjahr'!B9, "") | C9: =IF(D9="","",IF($H$3="BE", INDIRECT("P"&MATCH(M9-0.001,$Q$4:$Q$20,-1)+4),D9)) | F9: 13 | G9: =IF(G$25="","",COUNTIF(C$4:C$38,F9)) -> 0 | H9: =IF(G$25="","",G9/G$25) -> #DIV/0! | I9: =+G7+G8+G9 -> 0 | J9: =+B9&D9 | M9: =IF(D9="","",IF($H$3="BE",100 * D9 / IF(E9="",$H$30,E9))) | O9: =IF($H$32="M", $H$35+7*(100-$H$35)/12, $H$35+15*(100-$H$35)/30) -> 75 | P9: 11 | Q9: =(O9-100*SUM($A$43:A47)/$H$30) -> 75
A10: 7 | B10: =IF('1. Halbjahr'!B10<>"", '1. Halbjahr'!B10, "") | C10: =IF(D10="","",IF($H$3="BE", INDIRECT("P"&MATCH(M10-0.001,$Q$4:$Q$20,-1)+4),D10)) | F10: 12 | G10: =IF(G$25="","",COUNTIF(C$4:C$38,F10)) -> 0 | H10: =IF(G$25="","",G10/G$25) -> #DIV/0! | J10: =+B10&D10 | M10: =IF(D10="","",IF($H$3="BE",100 * D10 / IF(E10="",$H$30,E10))) | O10: =IF($H$32="M", $H$35+6*(100-$H$35)/12, $H$35+12*(100-$H$35)/30) -> 70 | P10: 10 | Q10: =(O10-100*SUM($A$43:A48)/$H$30) -> 70
A11: 8 | B11: =IF('1. Halbjahr'!B11<>"", '1. Halbjahr'!B11, "") | C11: =IF(D11="","",IF($H$3="BE", INDIRECT("P"&MATCH(M11-0.001,$Q$4:$Q$20,-1)+4),D11)) | F11: 11 | G11: =IF(G$25="","",COUNTIF(C$4:C$38,F11)) -> 0 | H11: =IF(G$25="","",G11/G$25) -> #DIV/0! | I11: =+H10+H11+H12 -> #DIV/0! | J11: =+B11&D11 | M11: =IF(D11="","",IF($H$3="BE",100 * D11 / IF(E11="",$H$30,E11))) | O11: =IF($H$32="M", $H$35+5*(100-$H$35)/12, $H$35+10*(100-$H$35)/30) -> 65 | P11: 9 | Q11: =(O11-100*SUM($A$43:A49)/$H$30) -> 65
A12: 9 | B12: =IF('1. Halbjahr'!B12<>"", '1. Halbjahr'!B12, "") | C12: =IF(D12="","",IF($H$3="BE", INDIRECT("P"&MATCH(M12-0.001,$Q$4:$Q$20,-1)+4),D12)) | F12: 10 | G12: =IF(G$25="","",COUNTIF(C$4:C$38,F12)) -> 0 | H12: =IF(G$25="","",G12/G$25) -> #DIV/0! | I12: =+G10+G11+G12 -> 0 | J12: =+B12&D12 | M12: =IF(D12="","",IF($H$3="BE",100 * D12 / IF(E12="",$H$30,E12))) | O12: =IF($H$32="M", $H$35+4*(100-$H$35)/12, $H$35+8*(100-$H$35)/30) -> 60 | P12: 8 | Q12: =(O12-100*SUM($A$43:A50)/$H$30) -> 60
A13: 10 | B13: =IF('1. Halbjahr'!B13<>"", '1. Halbjahr'!B13, "") | C13: =IF(D13="","",IF($H$3="BE", INDIRECT("P"&MATCH(M13-0.001,$Q$4:$Q$20,-1)+4),D13)) | F13: 9 | G13: =IF(G$25="","",COUNTIF(C$4:C$38,F13)) -> 0 | H13: =IF(G$25="","",G13/G$25) -> #DIV/0! | J13: =+B13&D13 | M13: =IF(D13="","",IF($H$3="BE",100 * D13 / IF(E13="",$H$30,E13))) | O13: =IF($H$32="M", $H$35+3*(100-$H$35)/12, $H$35+6*(100-$H$35)/30) -> 55 | P13: 7 | Q13: =(O13-100*SUM($A$43:A51)/$H$30) -> 55
A14: 11 | B14: =IF('1. Halbjahr'!B14<>"", '1. Halbjahr'!B14, "") | C14: =IF(D14="","",IF($H$3="BE", INDIRECT("P"&MATCH(M14-0.001,$Q$4:$Q$20,-1)+4),D14)) | F14: 8 | G14: =IF(G$25="","",COUNTIF(C$4:C$38,F14)) -> 0 | H14: =IF(G$25="","",G14/G$25) -> #DIV/0! | I14: =+H13+H14+H15 -> #DIV/0! | J14: =+B14&D14 | M14: =IF(D14="","",IF($H$3="BE",100 * D14 / IF(E14="",$H$30,E14))) | O14: =IF($H$32="M", $H$35+2*(100-$H$35)/12, $H$35+4*(100-$H$35)/30) -> 50 | P14: 6 | Q14: =(O14-100*SUM($A$43:A52)/$H$30) -> 50
A15: 12 | B15: =IF('1. Halbjahr'!B15<>"", '1. Halbjahr'!B15, "") | C15: =IF(D15="","",IF($H$3="BE", INDIRECT("P"&MATCH(M15-0.001,$Q$4:$Q$20,-1)+4),D15)) | F15: 7 | G15: =IF(G$25="","",COUNTIF(C$4:C$38,F15)) -> 0 | H15: =IF(G$25="","",G15/G$25) -> #DIV/0! | I15: =+G13+G14+G15 -> 0 | J15: =+B15&D15 | M15: =IF(D15="","",IF($H$3="BE",100 * D15 / IF(E15="",$H$30,E15))) | O15: =IF($H$32="M", $H$35+1*(100-$H$35)/12, $H$35+2*(100-$H$35)/30) -> 45 | P15: 5 | Q15: =(O15-100*SUM($A$43:A53)/$H$30) -> 45
A16: 13 | B16: =IF('1. Halbjahr'!B16<>"", '1. Halbjahr'!B16, "") | C16: =IF(D16="","",IF($H$3="BE", INDIRECT("P"&MATCH(M16-0.001,$Q$4:$Q$20,-1)+4),D16)) | F16: 6 | G16: =IF(G$25="","",COUNTIF(C$4:C$38,F16)) -> 0 | H16: =IF(G$25="","",G16/G$25) -> #DIV/0! | J16: =+B16&D16 | M16: =IF(D16="","",IF($H$3="BE",100 * D16 / IF(E16="",$H$30,E16))) | O16: =$H$35 -> 40 | P16: 4 | Q16: =(O16-100*SUM($A$43:A54)/$H$30) -> 40
A17: 14 | B17: =IF('1. Halbjahr'!B17<>"", '1. Halbjahr'!B17, "") | C17: =IF(D17="","",IF($H$3="BE", INDIRECT("P"&MATCH(M17-0.001,$Q$4:$Q$20,-1)+4),D17)) | F17: 5 | G17: =IF(G$25="","",COUNTIF(C$4:C$38,F17)) -> 0 | H17: =IF(G$25="","",G17/G$25) -> #DIV/0! | I17: =+H16+H17+H18 -> #DIV/0! | J17: =+B17&D17 | M17: =IF(D17="","",IF($H$3="BE",100 * D17 / IF(E17="",$H$30,E17))) | O17: =($H$34+2*($H$35-$H$34)/3) -> 33.333333 | P17: 3 | Q17: =(O17-100*SUM($A$43:A55)/$H$30) -> 33.333333
A18: 15 | B18: =IF('1. Halbjahr'!B18<>"", '1. Halbjahr'!B18, "") | C18: =IF(D18="","",IF($H$3="BE", INDIRECT("P"&MATCH(M18-0.001,$Q$4:$Q$20,-1)+4),D18)) | F18: 4 | G18: =IF(G$25="","",COUNTIF(C$4:C$38,F18)) -> 0 | H18: =IF(G$25="","",G18/G$25) -> #DIV/0! | I18: =+G16+G17+G18 -> 0 | J18: =+B18&D18 | M18: =IF(D18="","",IF($H$3="BE",100 * D18 / IF(E18="",$H$30,E18))) | O18: =($H$34+($H$35-$H$34)/3) -> 26.666667 | P18: 2 | Q18: =(O18-100*SUM($A$43:A56)/$H$30) -> 26.666667
A19: 16 | B19: =IF('1. Halbjahr'!B19<>"", '1. Halbjahr'!B19, "") | C19: =IF(D19="","",IF($H$3="BE", INDIRECT("P"&MATCH(M19-0.001,$Q$4:$Q$20,-1)+4),D19)) | F19: 3 | G19: =IF(G$25="","",COUNTIF(C$4:C$38,F19)) -> 0 | H19: =IF(G$25="","",G19/G$25) -> #DIV/0! | J19: =+B19&D19 | M19: =IF(D19="","",IF($H$3="BE",100 * D19 / IF(E19="",$H$30,E19))) | O19: =$H$34-0.01 -> 19.99 | P19: 1 | Q19: =(O19-100*SUM($A$43:A57)/$H$30) -> 19.99
A20: 17 | B20: =IF('1. Halbjahr'!B20<>"", '1. Halbjahr'!B20, "") | C20: =IF(D20="","",IF($H$3="BE", INDIRECT("P"&MATCH(M20-0.001,$Q$4:$Q$20,-1)+4),D20)) | F20: 2 | G20: =IF(G$25="","",COUNTIF(C$4:C$38,F20)) -> 0 | H20: =IF(G$25="","",G20/G$25) -> #DIV/0! | I20: =+H19+H20+H21 -> #DIV/0! | J20: =+B20&D20 | M20: =IF(D20="","",IF($H$3="BE",100 * D20 / IF(E20="",$H$30,E20))) | O20: 0 | P20: 0 | Q20: 0
A21: 18 | B21: =IF('1. Halbjahr'!B21<>"", '1. Halbjahr'!B21, "") | C21: =IF(D21="","",IF($H$3="BE", INDIRECT("P"&MATCH(M21-0.001,$Q$4:$Q$20,-1)+4),D21)) | F21: 1 | G21: =IF(G$25="","",COUNTIF(C$4:C$38,F21)) -> 0 | H21: =IF(G$25="","",G21/G$25) -> #DIV/0! | I21: =+G19+G20+G21 -> 0 | J21: =+B21&D21 | M21: =IF(D21="","",IF($H$3="BE",100 * D21 / IF(E21="",$H$30,E21)))
A22: 19 | B22: =IF('1. Halbjahr'!B22<>"", '1. Halbjahr'!B22, "") | C22: =IF(D22="","",IF($H$3="BE", INDIRECT("P"&MATCH(M22-0.001,$Q$4:$Q$20,-1)+4),D22)) | F22: 0 | G22: =IF(G$25="","",COUNTIF(C$4:C$38,F22)) -> 0 | H22: =IF(G$25="","",G22/G$25) -> #DIV/0! | I22: =+H22 -> #DIV/0! | J22: =+B22&D22 | M22: =IF(D22="","",IF($H$3="BE",100 * D22 / IF(E22="",$H$30,E22)))
A23: 20 | B23: =IF('1. Halbjahr'!B23<>"", '1. Halbjahr'!B23, "") | C23: =IF(D23="","",IF($H$3="BE", INDIRECT("P"&MATCH(M23-0.001,$Q$4:$Q$20,-1)+4),D23)) | F23: Schnitt | G23: =AVERAGE(C4:C38) -> #DIV/0! | H23: =+(17-G23)/3 -> #DIV/0! | I23: =+G22 -> 0 | J23: =+B23&D23 | M23: =IF(D23="","",IF($H$3="BE",100 * D23 / IF(E23="",$H$30,E23)))
A24: 21 | B24: =IF('1. Halbjahr'!B24<>"", '1. Halbjahr'!B24, "") | C24: =IF(D24="","",IF($H$3="BE", INDIRECT("P"&MATCH(M24-0.001,$Q$4:$Q$20,-1)+4),D24)) | J24: =+B24&D24 | M24: =IF(D24="","",IF($H$3="BE",100 * D24 / IF(E24="",$H$30,E24)))
A25: 22 | B25: =IF('1. Halbjahr'!B25<>"", '1. Halbjahr'!B25, "") | C25: =IF(D25="","",IF($H$3="BE", INDIRECT("P"&MATCH(M25-0.001,$Q$4:$Q$20,-1)+4),D25)) | F25: Teiln.: | G25: =COUNT(D4:D38) -> 0 | J25: =+B25&D25 | M25: =IF(D25="","",IF($H$3="BE",100 * D25 / IF(E25="",$H$30,E25)))
A26: 23 | B26: =IF('1. Halbjahr'!B26<>"", '1. Halbjahr'!B26, "") | C26: =IF(D26="","",IF($H$3="BE", INDIRECT("P"&MATCH(M26-0.001,$Q$4:$Q$20,-1)+4),D26)) | F26: Fehlend | G26: =+G27-G25 -> 0 | J26: =+B26&D26 | M26: =IF(D26="","",IF($H$3="BE",100 * D26 / IF(E26="",$H$30,E26)))
A27: 24 | B27: =IF('1. Halbjahr'!B27<>"", '1. Halbjahr'!B27, "") | C27: =IF(D27="","",IF($H$3="BE", INDIRECT("P"&MATCH(M27-0.001,$Q$4:$Q$20,-1)+4),D27)) | F27: Gesamt | G27: =35-COUNTIF(J4:J38,"") -> 0 | J27: =+B27&D27 | M27: =IF(D27="","",IF($H$3="BE",100 * D27 / IF(E27="",$H$30,E27)))
A28: 25 | B28: =IF('1. Halbjahr'!B28<>"", '1. Halbjahr'!B28, "") | C28: =IF(D28="","",IF($H$3="BE", INDIRECT("P"&MATCH(M28-0.001,$Q$4:$Q$20,-1)+4),D28)) | J28: =+B28&D28 | M28: =IF(D28="","",IF($H$3="BE",100 * D28 / IF(E28="",$H$30,E28)))
A29: 26 | B29: =IF('1. Halbjahr'!B29<>"", '1. Halbjahr'!B29, "") | C29: =IF(D29="","",IF($H$3="BE", INDIRECT("P"&MATCH(M29-0.001,$Q$4:$Q$20,-1)+4),D29)) | F29: Bewertungseinheiten gesamt | J29: =+B29&D29 | M29: =IF(D29="","",IF($H$3="BE",100 * D29 / IF(E29="",$H$30,E29)))
A30: 27 | B30: =IF('1. Halbjahr'!B30<>"", '1. Halbjahr'!B30, "") | C30: =IF(D30="","",IF($H$3="BE", INDIRECT("P"&MATCH(M30-0.001,$Q$4:$Q$20,-1)+4),D30)) | H30: 35 | J30: =+B30&D30 | M30: =IF(D30="","",IF($H$3="BE",100 * D30 / IF(E30="",$H$30,E30)))
A31: 28 | B31: =IF('1. Halbjahr'!B31<>"", '1. Halbjahr'!B31, "") | C31: =IF(D31="","",IF($H$3="BE", INDIRECT("P"&MATCH(M31-0.001,$Q$4:$Q$20,-1)+4),D31)) | J31: =+B31&D31 | M31: =IF(D31="","",IF($H$3="BE",100 * D31 / IF(E31="",$H$30,E31)))
A32: 29 | B32: =IF('1. Halbjahr'!B32<>"", '1. Halbjahr'!B32, "") | C32: =IF(D32="","",IF($H$3="BE", INDIRECT("P"&MATCH(M32-0.001,$Q$4:$Q$20,-1)+4),D32)) | F32: Schlüssel | H32: M | J32: =+B32&D32 | M32: =IF(D32="","",IF($H$3="BE",100 * D32 / IF(E32="",$H$30,E32)))
A33: 30 | B33: =IF('1. Halbjahr'!B33<>"", '1. Halbjahr'!B33, "") | C33: =IF(D33="","",IF($H$3="BE", INDIRECT("P"&MATCH(M33-0.001,$Q$4:$Q$20,-1)+4),D33)) | F33: Bereich Note 5 | J33: =+B33&D33 | M33: =IF(D33="","",IF($H$3="BE",100 * D33 / IF(E33="",$H$30,E33)))
A34: 31 | B34: =IF('1. Halbjahr'!B34<>"", '1. Halbjahr'!B34, "") | C34: =IF(D34="","",IF($H$3="BE", INDIRECT("P"&MATCH(M34-0.001,$Q$4:$Q$20,-1)+4),D34)) | F34: von Untergrenze | H34: 20 | I34: % | J34: =+B34&D34 | M34: =IF(D34="","",IF($H$3="BE",100 * D34 / IF(E34="",$H$30,E34)))
A35: 32 | B35: =IF('1. Halbjahr'!B35<>"", '1. Halbjahr'!B35, "") | C35: =IF(D35="","",IF($H$3="BE", INDIRECT("P"&MATCH(M35-0.001,$Q$4:$Q$20,-1)+4),D35)) | F35: bis Obergrenze | H35: 40 | I35: % | J35: =+B35&D35 | M35: =IF(D35="","",IF($H$3="BE",100 * D35 / IF(E35="",$H$30,E35)))
A36: 33 | B36: =IF('1. Halbjahr'!B36<>"", '1. Halbjahr'!B36, "") | C36: =IF(D36="","",IF($H$3="BE", INDIRECT("P"&MATCH(M36-0.001,$Q$4:$Q$20,-1)+4),D36)) | J36: =+B36&D36 | M36: =IF(D36="","",IF($H$3="BE",100 * D36 / IF(E36="",$H$30,E36)))
A37: 34 | B37: =IF('1. Halbjahr'!B37<>"", '1. Halbjahr'!B37, "") | C37: =IF(D37="","",IF($H$3="BE", INDIRECT("P"&MATCH(M37-0.001,$Q$4:$Q$20,-1)+4),D37)) | J37: =+B37&D37 | M37: =IF(D37="","",IF($H$3="BE",100 * D37 / IF(E37="",$H$30,E37)))
A38: 35 | B38: =IF('1. Halbjahr'!B38<>"", '1. Halbjahr'!B38, "") | C38: =IF(D38="","",IF($H$3="BE", INDIRECT("P"&MATCH(M38-0.001,$Q$4:$Q$20,-1)+4),D38)) | J38: =+B38&D38 | M38: =IF(D38="","",IF($H$3="BE",100 * D38 / IF(E38="",$H$30,E38)))
B40: Breite Punkte | C40: Bewertungs- | E40: Kontrolle
B41: angepasst | C41: einheiten | E41: Alarm bei Abweichung
...

Sheet I2SA
B1: I - 2. Schulaufgabe aus | C1: =IF('1. Halbjahr'!E1="","",'1. Halbjahr'!E1) | F1: Datum:
B2: Klasse: | C2: =IF('1. Halbjahr'!B1="","",'1. Halbjahr'!B1) | F2: Lehrer/-in: | G2: =IF('1. Halbjahr'!K1="","",'1. Halbjahr'!K1)
A3: Nr | B3: Name | C3: Punkte | D3: =IF(H3="BE",H3,"") -> BE | E3: NT | G3: Eingabe über: | H3: BE | M3: Prozentsatz erreicht | O3: Notenschluessel | Q3: modifiziert
A4: 1 | B4: =IF('1. Halbjahr'!B4<>"", '1. Halbjahr'!B4, "") | C4: =IF(D4="","",IF($H$3="BE", INDIRECT("P"&MATCH(M4-0.001,$Q$4:$Q$20,-1)+4),D4)) | J4: =+B4&D4 | M4: =IF(D4="","",IF($H$3="BE",100 * D4 / IF(E4="",$H$30,E4))) | O4: =IF($H$32="M", $H$35+12*(100-$H$35)/12, $H$35+30*(100-$H$35)/30) -> 100 | Q4: 100
A5: 2 | B5: =IF('1. Halbjahr'!B5<>"", '1. Halbjahr'!B5, "") | C5: =IF(D5="","",IF($H$3="BE", INDIRECT("P"&MATCH(M5-0.001,$Q$4:$Q$20,-1)+4),D5)) | F5: Auswertung | J5: =+B5&D5 | M5: =IF(D5="","",IF($H$3="BE",100 * D5 / IF(E5="",$H$30,E5))) | O5: =IF($H$32="M", $H$35+11*(100-$H$35)/12, $H$35+27*(100-$H$35)/30) -> 95 | P5: 15 | Q5: =(O5-100*SUM($A$43:A43)/$H$30) -> 95
A6: 3 | B6: =IF('1. Halbjahr'!B6<>"", '1. Halbjahr'!B6, "") | C6: =IF(D6="","",IF($H$3="BE", INDIRECT("P"&MATCH(M6-0.001,$Q$4:$Q$20,-1)+4),D6)) | F6: Punkte | G6: Anzahl | H6: Anteil | J6: =+B6&D6 | M6: =IF(D6="","",IF($H$3="BE",100 * D6 / IF(E6="",$H$30,E6))) | O6: =IF($H$32="M", $H$35+10*(100-$H$35)/12, $H$35+24*(100-$H$35)/30) -> 90 | P6: 14 | Q6: =(O6-100*SUM($A$43:A44)/$H$30) -> 90
A7: 4 | B7: =IF('1. Halbjahr'!B7<>"", '1. Halbjahr'!B7, "") | C7: =IF(D7="","",IF($H$3="BE", INDIRECT("P"&MATCH(M7-0.001,$Q$4:$Q$20,-1)+4),D7)) | F7: 15 | G7: =IF(G$25="","",COUNTIF(C$4:C$38,F7)) -> 0 | H7: =IF(G$25="","",G7/G$25) -> #DIV/0! | J7: =+B7&D7 | M7: =IF(D7="","",IF($H$3="BE",100 * D7 / IF(E7="",$H$30,E7))) | O7: =IF($H$32="M", $H$35+9*(100-$H$35)/12, $H$35+21*(100-$H$35)/30) -> 85 | P7: 13 | Q7: =(O7-100*SUM($A$43:A45)/$H$30) -> 85
A8: 5 | B8: =IF('1. Halbjahr'!B8<>"", '1. Halbjahr'!B8, "") | C8: =IF(D8="","",IF($H$3="BE", INDIRECT("P"&MATCH(M8-0.001,$Q$4:$Q$20,-1)+4),D8)) | F8: 14 | G8: =IF(G$25="","",COUNTIF(C$4:C$38,F8)) -> 0 | H8: =IF(G$25="","",G8/G$25) -> #DIV/0! | I8: =+H7+H8+H9 -> #DIV/0! | J8: =+B8&D8 | M8: =IF(D8="","",IF($H$3="BE",100 * D8 / IF(E8="",$H$30,E8))) | O8: =IF($H$32="M", $H$35+8*(100-$H$35)/12, $H$35+18*(100-$H$35)/30) -> 80 | P8: 12 | Q8: =(O8-100*SUM($A$43:A46)/$H$30) -> 80
A9: 6 | B9: =IF('1. Halbjahr'!B9<>"", '1. Halbjahr'!B9, "") | C9: =IF(D9="","",IF($H$3="BE", INDIRECT("P"&MATCH(M9-0.001,$Q$4:$Q$20,-1)+4),D9)) | F9: 13 | G9: =IF(G$25="","",COUNTIF(C$4:C$38,F9)) -> 0 | H9: =IF(G$25="","",G9/G$25) -> #DIV/0! | I9: =+G7+G8+G9 -> 0 | J9: =+B9&D9 | M9: =IF(D9="","",IF($H$3="BE",100 * D9 / IF(E9="",$H$30,E9))) | O9: =IF($H$32="M", $H$35+7*(100-$H$35)/12, $H$35+15*(100-$H$35)/30) -> 75 | P9: 11 | Q9: =(O9-100*SUM($A$43:A47)/$H$30) -> 75
A10: 7 | B10: =IF('1. Halbjahr'!B10<>"", '1. Halbjahr'!B10, "") | C10: =IF(D10="","",IF($H$3="BE", INDIRECT("P"&MATCH(M10-0.001,$Q$4:$Q$20,-1)+4),D10)) | F10: 12 | G10: =IF(G$25="","",COUNTIF(C$4:C$38,F10)) -> 0 | H10: =IF(G$25="","",G10/G$25) -> #DIV/0! | J10: =+B10&D10 | M10: =IF(D10="","",IF($H$3="BE",100 * D10 / IF(E10="",$H$30,E10))) | O10: =IF($H$32="M", $H$35+6*(100-$H$35)/12, $H$35+12*(100-$H$35)/30) -> 70 | P10: 10 | Q10: =(O10-100*SUM($A$43:A48)/$H$30) -> 70
A11: 8 | B11: =IF('1. Halbjahr'!B11<>"", '1. Halbjahr'!B11, "") | C11: =IF(D11="","",IF($H$3="BE", INDIRECT("P"&MATCH(M11-0.001,$Q$4:$Q$20,-1)+4),D11)) | F11: 11 | G11: =IF(G$25="","",COUNTIF(C$4:C$38,F11)) -> 0 | H11: =IF(G$25="","",G11/G$25) -> #DIV/0! | I11: =+H10+H11+H12 -> #DIV/0! | J11: =+B11&D11 | M11: =IF(D11="","",IF($H$3="BE",100 * D11 / IF(E11="",$H$30,E11))) | O11: =IF($H$32="M", $H$35+5*(100-$H$35)/12, $H$35+10*(100-$H$35)/30) -> 65 | P11: 9 | Q11: =(O11-100*SUM($A$43:A49)/$H$30) -> 65
A12: 9 | B12: =IF('1. Halbjahr'!B12<>"", '1. Halbjahr'!B12, "") | C12: =IF(D12="","",IF($H$3="BE", INDIRECT("P"&MATCH(M12-0.001,$Q$4:$Q$20,-1)+4),D12)) | F12: 10 | G12: =IF(G$25="","",COUNTIF(C$4:C$38,F12)) -> 0 | H12: =IF(G$25="","",G12/G$25) -> #DIV/0! | I12: =+G10+G11+G12 -> 0 | J12: =+B12&D12 | M12: =IF(D12="","",IF($H$3="BE",100 * D12 / IF(E12="",$H$30,E12))) | O12: =IF($H$32="M", $H$35+4*(100-$H$35)/12, $H$35+8*(100-$H$35)/30) -> 60 | P12: 8 | Q12: =(O12-100*SUM($A$43:A50)/$H$30) -> 60
A13: 10 | B13: =IF('1. Halbjahr'!B13<>"", '1. Halbjahr'!B13, "") | C13: =IF(D13="","",IF($H$3="BE", INDIRECT("P"&MATCH(M13-0.001,$Q$4:$Q$20,-1)+4),D13)) | F13: 9 | G13: =IF(G$25="","",COUNTIF(C$4:C$38,F13)) -> 0 | H13: =IF(G$25="","",G13/G$25) -> #DIV/0! | J13: =+B13&D13 | M13: =IF(D13="","",IF($H$3="BE",100 * D13 / IF(E13="",$H$30,E13))) | O13: =IF($H$32="M", $H$35+3*(100-$H$35)/12, $H$35+6*(100-$H$35)/30) -> 55 | P13: 7 | Q13: =(O13-100*SUM($A$43:A51)/$H$30) -> 55
A14: 11 | B14: =IF('1. Halbjahr'!B14<>"", '1. Halbjahr'!B14, "") | C14: =IF(D14="","",IF($H$3="BE", INDIRECT("P"&MATCH(M14-0.001,$Q$4:$Q$20,-1)+4),D14)) | F14: 8 | G14: =IF(G$25="","",COUNTIF(C$4:C$38,F14)) -> 0 | H14: =IF(G$25="","",G14/G$25) -> #DIV/0! | I14: =+H13+H14+H15 -> #DIV/0! | J14: =+B14&D14 | M14: =IF(D14="","",IF($H$3="BE",100 * D14 / IF(E14="",$H$30,E14))) | O14: =IF($H$32="M", $H$35+2*(100-$H$35)/12, $H$35+4*(100-$H$35)/30) -> 50 | P14: 6 | Q14: =(O14-100*SUM($A$43:A52)/$H$30) -> 50
A15: 12 | B15: =IF('1. Halbjahr'!B15<>"", '1. Halbjahr'!B15, "") | C15: =IF(D15="","",IF($H$3="BE", INDIRECT("P"&MATCH(M15-0.001,$Q$4:$Q$20,-1)+4),D15)) | F15: 7 | G15: =IF(G$25="","",COUNTIF(C$4:C$38,F15)) -> 0 | H15: =IF(G$25="","",G15/G$25) -> #DIV/0! | I15: =+G13+G14+G15 -> 0 | J15: =+B15&D15 | M15: =IF(D15="","",IF($H$3="BE",100 * D15 / IF(E15="",$H$30,E15))) | O15: =IF($H$32="M", $H$35+1*(100-$H$35)/12, $H$35+2*(100-$H$35)/30) -> 45 | P15: 5 | Q15: =(O15-100*SUM($A$43:A53)/$H$30) -> 45
A16: 13 | B16: =IF('1. Halbjahr'!B16<>"", '1. Halbjahr'!B16, "") | C16: =IF(D16="","",IF($H$3="BE", INDIRECT("P"&MATCH(M16-0.001,$Q$4:$Q$20,-1)+4),D16)) | F16: 6 | G16: =IF(G$25="","",COUNTIF(C$4:C$38,F16)) -> 0 | H16: =IF(G$25="","",G16/G$25) -> #DIV/0! | J16: =+B16&D16 | M16: =IF(D16="","",IF($H$3="BE",100 * D16 / IF(E16="",$H$30,E16))) | O16: =$H$35 -> 40 | P16: 4 | Q16: =(O16-100*SUM($A$43:A54)/$H$30) -> 40
A17: 14 | B17: =IF('1. Halbjahr'!B17<>"", '1. Halbjahr'!B17, "") | C17: =IF(D17="","",IF($H$3="BE", INDIRECT("P"&MATCH(M17-0.001,$Q$4:$Q$20,-1)+4),D17)) | F17: 5 | G17: =IF(G$25="","",COUNTIF(C$4:C$38,F17)) -> 0 | H17: =IF(G$25="","",G17/G$25) -> #DIV/0! | I17: =+H16+H17+H18 -> #DIV/0! | J17: =+B17&D17 | M17: =IF(D17="","",IF($H$3="BE",100 * D17 / IF(E17="",$H$30,E17))) | O17: =($H$34+2*($H$35-$H$34)/3) -> 33.333333 | P17: 3 | Q17: =(O17-100*SUM($A$43:A55)/$H$30) -> 33.333333
A18: 15 | B18: =IF('1. Halbjahr'!B18<>"", '1. Halbjahr'!B18, "") | C18: =IF(D18="","",IF($H$3="BE", INDIRECT("P"&MATCH(M18-0.001,$Q$4:$Q$20,-1)+4),D18)) | F18: 4 | G18: =IF(G$25="","",COUNTIF(C$4:C$38,F18)) -> 0 | H18: =IF(G$25="","",G18/G$25) -> #DIV/0! | I18: =+G16+G17+G18 -> 0 | J18: =+B18&D18 | M18: =IF(D18="","",IF($H$3="BE",100 * D18 / IF(E18="",$H$30,E18))) | O18: =($H$34+($H$35-$H$34)/3) -> 26.666667 | P18: 2 | Q18: =(O18-100*SUM($A$43:A56)/$H$30) -> 26.666667
A19: 16 | B19: =IF('1. Halbjahr'!B19<>"", '1. Halbjahr'!B19, "") | C19: =IF(D19="","",IF($H$3="BE", INDIRECT("P"&MATCH(M19-0.001,$Q$4:$Q$20,-1)+4),D19)) | F19: 3 | G19: =IF(G$25="","",COUNTIF(C$4:C$38,F19)) -> 0 | H19: =IF(G$25="","",G19/G$25) -> #DIV/0! | J19: =+B19&D19 | M19: =IF(D19="","",IF($H$3="BE",100 * D19 / IF(E19="",$H$30,E19))) | O19: =$H$34-0.01 -> 19.99 | P19: 1 | Q19: =(O19-100*SUM($A$43:A57)/$H$30) -> 19.99
A20: 17 | B20: =IF('1. Halbjahr'!B20<>"", '1. Halbjahr'!B20, "") | C20: =IF(D20="","",IF($H$3="BE", INDIRECT("P"&MATCH(M20-0.001,$Q$4:$Q$20,-1)+4),D20)) | F20: 2 | G20: =IF(G$25="","",COUNTIF(C$4:C$38,F20)) -> 0 | H20: =IF(G$25="","",G20/G$25) -> #DIV/0! | I20: =+H19+H20+H21 -> #DIV/0! | J20: =+B20&D20 | M20: =IF(D20="","",IF($H$3="BE",100 * D20 / IF(E20="",$H$30,E20))) | O20: 0 | P20: 0 | Q20: 0
A21: 18 | B21: =IF('1. Halbjahr'!B21<>"", '1. Halbjahr'!B21, "") | C21: =IF(D21="","",IF($H$3="BE", INDIRECT("P"&MATCH(M21-0.001,$Q$4:$Q$20,-1)+4),D21)) | F21: 1 | G21: =IF(G$25="","",COUNTIF(C$4:C$38,F21)) -> 0 | H21: =IF(G$25="","",G21/G$25) -> #DIV/0! | I21: =+G19+G20+G21 -> 0 | J21: =+B21&D21 | M21: =IF(D21="","",IF($H$3="BE",100 * D21 / IF(E21="",$H$30,E21)))
A22: 19 | B22: =IF('1. Halbjahr'!B22<>"", '1. Halbjahr'!B22, "") | C22: =IF(D22="","",IF($H$3="BE", INDIRECT("P"&MATCH(M22-0.001,$Q$4:$Q$20,-1)+4),D22)) | F22: 0 | G22: =IF(G$25="","",COUNTIF(C$4:C$38,F22)) -> 0 | H22: =IF(G$25="","",G22/G$25) -> #DIV/0! | I22: =+H22 -> #DIV/0! | J22: =+B22&D22 | M22: =IF(D22="","",IF($H$3="BE",100 * D22 / IF(E22="",$H$30,E22)))
A23: 20 | B23: =IF('1. Halbjahr'!B23<>"", '1. Halbjahr'!B23, "") | C23: =IF(D23="","",IF($H$3="BE", INDIRECT("P"&MATCH(M23-0.001,$Q$4:$Q$20,-1)+4),D23)) | F23: Schnitt | G23: =AVERAGE(C4:C38) -> #DIV/0! | H23: =+(17-G23)/3 -> #DIV/0! | I23: =+G22 -> 0 | J23: =+B23&D23 | M23: =IF(D23="","",IF($H$3="BE",100 * D23 / IF(E23="",$H$30,E23)))
A24: 21 | B24: =IF('1. Halbjahr'!B24<>"", '1. Halbjahr'!B24, "") | C24: =IF(D24="","",IF($H$3="BE", INDIRECT("P"&MATCH(M24-0.001,$Q$4:$Q$20,-1)+4),D24)) | J24: =+B24&D24 | M24: =IF(D24="","",IF($H$3="BE",100 * D24 / IF(E24="",$H$30,E24)))
A25: 22 | B25: =IF('1. Halbjahr'!B25<>"", '1. Halbjahr'!B25, "") | C25: =IF(D25="","",IF($H$3="BE", INDIRECT("P"&MATCH(M25-0.001,$Q$4:$Q$20,-1)+4),D25)) | F25: Teiln.: | G25: =COUNT(D4:D38) -> 0 | J25: =+B25&D25 | M25: =IF(D25="","",IF($H$3="BE",100 * D25 / IF(E25="",$H$30,E25)))
A26: 23 | B26: =IF('1. Halbjahr'!B26<>"", '1. Halbjahr'!B26, "") | C26: =IF(D26="","",IF($H$3="BE", INDIRECT("P"&MATCH(M26-0.001,$Q$4:$Q$20,-1)+4),D26)) | F26: Fehlend | G26: =+G27-G25 -> 0 | J26: =+B26&D26 | M26: =IF(D26="","",IF($H$3="BE",100 * D26 / IF(E26="",$H$30,E26)))
A27: 24 | B27: =IF('1. Halbjahr'!B27<>"", '1. Halbjahr'!B27, "") | C27: =IF(D27="","",IF($H$3="BE", INDIRECT("P"&MATCH(M27-0.001,$Q$4:$Q$20,-1)+4),D27)) | F27: Gesamt | G27: =35-COUNTIF(J4:J38,"") -> 0 | J27: =+B27&D27 | M27: =IF(D27="","",IF($H$3="BE",100 * D27 / IF(E27="",$H$30,E27)))
A28: 25 | B28: =IF('1. Halbjahr'!B28<>"", '1. Halbjahr'!B28, "") | C28: =IF(D28="","",IF($H$3="BE", INDIRECT("P"&MATCH(M28-0.001,$Q$4:$Q$20,-1)+4),D28)) | J28: =+B28&D28 | M28: =IF(D28="","",IF($H$3="BE",100 * D28 / IF(E28="",$H$30,E28)))
A29: 26 | B29: =IF('1. Halbjahr'!B29<>"", '1. Halbjahr'!B29, "") | C29: =IF(D29="","",IF($H$3="BE", INDIRECT("P"&MATCH(M29-0.001,$Q$4:$Q$20,-1)+4),D29)) | F29: Bewertungseinheiten gesamt | J29: =+B29&D29 | M29: =IF(D29="","",IF($H$3="BE",100 * D29 / IF(E29="",$H$30,E29)))
A30: 27 | B30: =IF('1. Halbjahr'!B30<>"", '1. Halbjahr'!B30, "") | C30: =IF(D30="","",IF($H$3="BE", INDIRECT("P"&MATCH(M30-0.001,$Q$4:$Q$20,-1)+4),D30)) | H30: 35 | J30: =+B30&D30 | M30: =IF(D30="","",IF($H$3="BE",100 * D30 / IF(E30="",$H$30,E30)))
A31: 28 | B31: =IF('1. Halbjahr'!B31<>"", '1. Halbjahr'!B31, "") | C31: =IF(D31="","",IF($H$3="BE", INDIRECT("P"&MATCH(M31-0.001,$Q$4:$Q$20,-1)+4),D31)) | J31: =+B31&D31 | M31: =IF(D31="","",IF($H$3="BE",100 * D31 / IF(E31="",$H$30,E31)))
A32: 29 | B32: =IF('1. Halbjahr'!B32<>"", '1. Halbjahr'!B32, "") | C32: =IF(D32="","",IF($H$3="BE", INDIRECT("P"&MATCH(M32-0.001,$Q$4:$Q$20,-1)+4),D32)) | F32: Schlüssel | H32: M | J32: =+B32&D32 | M32: =IF(D32="","",IF($H$3="BE",100 * D32 / IF(E32="",$H$30,E32)))
A33: 30 | B33: =IF('1. Halbjahr'!B33<>"", '1. Halbjahr'!B33, "") | C33: =IF(D33="","",IF($H$3="BE", INDIRECT("P"&MATCH(M33-0.001,$Q$4:$Q$20,-1)+4),D33)) | F33: Bereich Note 5 | J33: =+B33&D33 | M33: =IF(D33="","",IF($H$3="BE",100 * D33 / IF(E33="",$H$30,E33)))
A34: 31 | B34: =IF('1. Halbjahr'!B34<>"", '1. Halbjahr'!B34, "") | C34: =IF(D34="","",IF($H$3="BE", INDIRECT("P"&MATCH(M34-0.001,$Q$4:$Q$20,-1)+4),D34)) | F34: von Untergrenze | H34: 20 | I34: % | J34: =+B34&D34 | M34: =IF(D34="","",IF($H$3="BE",100 * D34 / IF(E34="",$H$30,E34)))
A35: 32 | B35: =IF('1. Halbjahr'!B35<>"", '1. Halbjahr'!B35, "") | C35: =IF(D35="","",IF($H$3="BE", INDIRECT("P"&MATCH(M35-0.001,$Q$4:$Q$20,-1)+4),D35)) | F35: bis Obergrenze | H35: 40 | I35: % | J35: =+B35&D35 | M35: =IF(D35="","",IF($H$3="BE",100 * D35 / IF(E35="",$H$30,E35)))
A36: 33 | B36: =IF('1. Halbjahr'!B36<>"", '1. Halbjahr'!B36, "") | C36: =IF(D36="","",IF($H$3="BE", INDIRECT("P"&MATCH(M36-0.001,$Q$4:$Q$20,-1)+4),D36)) | J36: =+B36&D36 | M36: =IF(D36="","",IF($H$3="BE",100 * D36 / IF(E36="",$H$30,E36)))
A37: 34 | B37: =IF('1. Halbjahr'!B37<>"", '1. Halbjahr'!B37, "") | C37: =IF(D37="","",IF($H$3="BE", INDIRECT("P"&MATCH(M37-0.001,$Q$4:$Q$20,-1)+4),D37)) | J37: =+B37&D37 | M37: =IF(D37="","",IF($H$3="BE",100 * D37 / IF(E37="",$H$30,E37)))
A38: 35 | B38: =IF('1. Halbjahr'!B38<>"", '1. Halbjahr'!B38, "") | C38: =IF(D38="","",IF($H$3="BE", INDIRECT("P"&MATCH(M38-0.001,$Q$4:$Q$20,-1)+4),D38)) | J38: =+B38&D38 | M38: =IF(D38="","",IF($H$3="BE",100 * D38 / IF(E38="",$H$30,E38)))
B40: Breite Punkte | C40: Bewertungs- | E40: Kontrolle
B41: angepasst | C41: einheiten | E41: Alarm bei Abweichung
...

Sheet I1KA
B1: I - 1. Kurzarbeit aus | C1: =IF('1. Halbjahr'!E1="","",'1. Halbjahr'!E1) | F1: Datum:
B2: Klasse: | C2: =IF('1. Halbjahr'!B1="","",'1. Halbjahr'!B1) | F2: Lehrer/-in: | G2: =IF('1. Halbjahr'!K1="","",'1. Halbjahr'!K1)
A3: Nr | B3: Name | C3: Punkte | D3: =IF(H3="BE",H3,"") -> BE | E3: NT | G3: Eingabe über: | H3: BE | M3: Prozentsatz erreicht | O3: Notenschluessel | Q3: modifiziert
A4: 1 | B4: =IF('1. Halbjahr'!B4<>"", '1. Halbjahr'!B4, "") | C4: =IF(D4="","",IF($H$3="BE", INDIRECT("P"&MATCH(M4-0.001,$Q$4:$Q$20,-1)+4),D4)) | J4: =+B4&D4 | M4: =IF(D4="","",IF($H$3="BE",100 * D4 / IF(E4="",$H$30,E4))) | O4: =IF($H$32="M", $H$35+12*(100-$H$35)/12, $H$35+30*(100-$H$35)/30) -> 100 | Q4: 100
A5: 2 | B5: =IF('1. Halbjahr'!B5<>"", '1. Halbjahr'!B5, "") | C5: =IF(D5="","",IF($H$3="BE", INDIRECT("P"&MATCH(M5-0.001,$Q$4:$Q$20,-1)+4),D5)) | F5: Auswertung | J5: =+B5&D5 | M5: =IF(D5="","",IF($H$3="BE",100 * D5 / IF(E5="",$H$30,E5))) | O5: =IF($H$32="M", $H$35+11*(100-$H$35)/12, $H$35+27*(100-$H$35)/30) -> 95 | P5: 15 | Q5: =(O5-100*SUM($A$43:A43)/$H$30) -> 95
A6: 3 | B6: =IF('1. Halbjahr'!B6<>"", '1. Halbjahr'!B6, "") | C6: =IF(D6="","",IF($H$3="BE", INDIRECT("P"&MATCH(M6-0.001,$Q$4:$Q$20,-1)+4),D6)) | F6: Punkte | G6: Anzahl | H6: Anteil | J6: =+B6&D6 | M6: =IF(D6="","",IF($H$3="BE",100 * D6 / IF(E6="",$H$30,E6))) | O6: =IF($H$32="M", $H$35+10*(100-$H$35)/12, $H$35+24*(100-$H$35)/30) -> 90 | P6: 14 | Q6: =(O6-100*SUM($A$43:A44)/$H$30) -> 90
A7: 4 | B7: =IF('1. Halbjahr'!B7<>"", '1. Halbjahr'!B7, "") | C7: =IF(D7="","",IF($H$3="BE", INDIRECT("P"&MATCH(M7-0.001,$Q$4:$Q$20,-1)+4),D7)) | F7: 15 | G7: =IF(G$25="","",COUNTIF(C$4:C$38,F7)) -> 0 | H7: =IF(G$25="","",G7/G$25) -> #DIV/0! | J7: =+B7&D7 | M7: =IF(D7="","",IF($H$3="BE",100 * D7 / IF(E7="",$H$30,E7))) | O7: =IF($H$32="M", $H$35+9*(100-$H$35)/12, $H$35+21*(100-$H$35)/30) -> 85 | P7: 13 | Q7: =(O7-100*SUM($A$43:A45)/$H$30) -> 85
A8: 5 | B8: =IF('1. Halbjahr'!B8<>"", '1. Halbjahr'!B8, "") | C8: =IF(D8="","",IF($H$3="BE", INDIRECT("P"&MATCH(M8-0.001,$Q$4:$Q$20,-1)+4),D8)) | F8: 14 | G8: =IF(G$25="","",COUNTIF(C$4:C$38,F8)) -> 0 | H8: =IF(G$25="","",G8/G$25) -> #DIV/0! | I8: =+H7+H8+H9 -> #DIV/0! | J8: =+B8&D8 | M8: =IF(D8="","",IF($H$3="BE",100 * D8 / IF(E8="",$H$30,E8))) | O8: =IF($H$32="M", $H$35+8*(100-$H$35)/12, $H$35+18*(100-$H$35)/30) -> 80 | P8: 12 | Q8: =(O8-100*SUM($A$43:A46)/$H$30) -> 80
A9: 6 | B9: =IF('1. Halbjahr'!B9<>"", '1. Halbjahr'!B9, "") | C9: =IF(D9="","",IF($H$3="BE", INDIRECT("P"&MATCH(M9-0.001,$Q$4:$Q$20,-1)+4),D9)) | F9: 13 | G9: =IF(G$25="","",COUNTIF(C$4:C$38,F9)) -> 0 | H9: =IF(G$25="","",G9/G$25) -> #DIV/0! | I9: =+G7+G8+G9 -> 0 | J9: =+B9&D9 | M9: =IF(D9="","",IF($H$3="BE",100 * D9 / IF(E9="",$H$30,E9))) | O9: =IF($H$32="M", $H$35+7*(100-$H$35)/12, $H$35+15*(100-$H$35)/30) -> 75 | P9: 11 | Q9: =(O9-100*SUM($A$43:A47)/$H$30) -> 75
A10: 7 | B10: =IF('1. Halbjahr'!B10<>"", '1. Halbjahr'!B10, "") | C10: =IF(D10="","",IF($H$3="BE", INDIRECT("P"&MATCH(M10-0.001,$Q$4:$Q$20,-1)+4),D10)) | F10: 12 | G10: =IF(G$25="","",COUNTIF(C$4:C$38,F10)) -> 0 | H10: =IF(G$25="","",G10/G$25) -> #DIV/0! | J10: =+B10&D10 | M10: =IF(D10="","",IF($H$3="BE",100 * D10 / IF(E10="",$H$30,E10))) | O10: =IF($H$32="M", $H$35+6*(100-$H$35)/12, $H$35+12*(100-$H$35)/30) -> 70 | P10: 10 | Q10: =(O10-100*SUM($A$43:A48)/$H$30) -> 70
A11: 8 | B11: =IF('1. Halbjahr'!B11<>"", '1. Halbjahr'!B11, "") | C11: =IF(D11="","",IF($H$3="BE", INDIRECT("P"&MATCH(M11-0.001,$Q$4:$Q$20,-1)+4),D11)) | F11: 11 | G11: =IF(G$25="","",COUNTIF(C$4:C$38,F11)) -> 0 | H11: =IF(G$25="","",G11/G$25) -> #DIV/0! | I11: =+H10+H11+H12 -> #DIV/0! | J11: =+B11&D11 | M11: =IF(D11="","",IF($H$3="BE",100 * D11 / IF(E11="",$H$30,E11))) | O11: =IF($H$32="M", $H$35+5*(100-$H$35)/12, $H$35+10*(100-$H$35)/30) -> 65 | P11: 9 | Q11: =(O11-100*SUM($A$43:A49)/$H$30) -> 65
A12: 9 | B12: =IF('1. Halbjahr'!B12<>"", '1. Halbjahr'!B12, "") | C12: =IF(D12="","",IF($H$3="BE", INDIRECT("P"&MATCH(M12-0.001,$Q$4:$Q$20,-1)+4),D12)) | F12: 10 | G12: =IF(G$25="","",COUNTIF(C$4:C$38,F12)) -> 0 | H12: =IF(G$25="","",G12/G$25) -> #DIV/0! | I12: =+G10+G11+G12 -> 0 | J12: =+B12&D12 | M12: =IF(D12="","",IF($H$3="BE",100 * D12 / IF(E12="",$H$30,E12))) | O12: =IF($H$32="M", $H$35+4*(100-$H$35)/12, $H$35+8*(100-$H$35)/30) -> 60 | P12: 8 | Q12: =(O12-100*SUM($A$43:A50)/$H$30) -> 60
A13: 10 | B13: =IF('1. Halbjahr'!B13<>"", '1. Halbjahr'!B13, "") | C13: =IF(D13="","",IF($H$3="BE", INDIRECT("P"&MATCH(M13-0.001,$Q$4:$Q$20,-1)+4),D13)) | F13: 9 | G13: =IF(G$25="","",COUNTIF(C$4:C$38,F13)) -> 0 | H13: =IF(G$25="","",G13/G$25) -> #DIV/0! | J13: =+B13&D13 | M13: =IF(D13="","",IF($H$3="BE",100 * D13 / IF(E13="",$H$30,E13))) | O13: =IF($H$32="M", $H$35+3*(100-$H$35)/12, $H$35+6*(100-$H$35)/30) -> 55 | P13: 7 | Q13: =(O13-100*SUM($A$43:A51)/$H$30) -> 55
A14: 11 | B14: =IF('1. Halbjahr'!B14<>"", '1. Halbjahr'!B14, "") | C14: =IF(D14="","",IF($H$3="BE", INDIRECT("P"&MATCH(M14-0.001,$Q$4:$Q$20,-1)+4),D14)) | F14: 8 | G14: =IF(G$25="","",COUNTIF(C$4:C$38,F14)) -> 0 | H14: =IF(G$25="","",G14/G$25) -> #DIV/0! | I14: =+H13+H14+H15 -> #DIV/0! | J14: =+B14&D14 | M14: =IF(D14="","",IF($H$3="BE",100 * D14 / IF(E14="",$H$30,E14))) | O14: =IF($H$32="M", $H$35+2*(100-$H$35)/12, $H$35+4*(100-$H$35)/30) -> 50 | P14: 6 | Q14: =(O14-100*SUM($A$43:A52)/$H$30) -> 50
A15: 12 | B15: =IF('1. Halbjahr'!B15<>"", '1. Halbjahr'!B15, "") | C15: =IF(D15="","",IF($H$3="BE", INDIRECT("P"&MATCH(M15-0.001,$Q$4:$Q$20,-1)+4),D15)) | F15: 7 | G15: =IF(G$25="","",COUNTIF(C$4:C$38,F15)) -> 0 | H15: =IF(G$25="","",G15/G$25) -> #DIV/0! | I15: =+G13+G14+G15 -> 0 | J15: =+B15&D15 | M15: =IF(D15="","",IF($H$3="BE",100 * D15 / IF(E15="",$H$30,E15))) | O15: =IF($H$32="M", $H$35+1*(100-$H$35)/12, $H$35+2*(100-$H$35)/30) -> 45 | P15: 5 | Q15: =(O15-100*SUM($A$43:A53)/$H$30) -> 45
A16: 13 | B16: =IF('1. Halbjahr'!B16<>"", '1. Halbjahr'!B16, "") | C16: =IF(D16="","",IF($H$3="BE", INDIRECT("P"&MATCH(M16-0.001,$Q$4:$Q$20,-1)+4),D16)) | F16: 6 | G16: =IF(G$25="","",COUNTIF(C$4:C$38,F16)) -> 0 | H16: =IF(G$25="","",G16/G$25) -> #DIV/0! | J16: =+B16&D16 | M16: =IF(D16="","",IF($H$3="BE",100 * D16 / IF(E16="",$H$30,E16))) | O16: =$H$35 -> 40 | P16: 4 | Q16: =(O16-100*SUM($A$43:A54)/$H$30) -> 40
A17: 14 | B17: =IF('1. Halbjahr'!B17<>"", '1. Halbjahr'!B17, "") | C17: =IF(D17="","",IF($H$3="BE", INDIRECT("P"&MATCH(M17-0.001,$Q$4:$Q$20,-1)+4),D17)) | F17: 5 | G17: =IF(G$25="","",COUNTIF(C$4:C$38,F17)) -> 0 | H17: =IF(G$25="","",G17/G$25) -> #DIV/0! | I17: =+H16+H17+H18 -> #DIV/0! | J17: =+B17&D17 | M17: =IF(D17="","",IF($H$3="BE",100 * D17 / IF(E17="",$H$30,E17))) | O17: =($H$34+2*($H$35-$H$34)/3) -> 33.333333 | P17: 3 | Q17: =(O17-100*SUM($A$43:A55)/$H$30) -> 33.333333
A18: 15 | B18: =IF('1. Halbjahr'!B18<>"", '1. Halbjahr'!B18, "") | C18: =IF(D18="","",IF($H$3="BE", INDIRECT("P"&MATCH(M18-0.001,$Q$4:$Q$20,-1)+4),D18)) | F18: 4 | G18: =IF(G$25="","",COUNTIF(C$4:C$38,F18)) -> 0 | H18: =IF(G$25="","",G18/G$25) -> #DIV/0! | I18: =+G16+G17+G18 -> 0 | J18: =+B18&D18 | M18: =IF(D18="","",IF($H$3="BE",100 * D18 / IF(E18="",$H$30,E18))) | O18: =($H$34+($H$35-$H$34)/3) -> 26.666667 | P18: 2 | Q18: =(O18-100*SUM($A$43:A56)/$H$30) -> 26.666667
A19: 16 | B19: =IF('1. Halbjahr'!B19<>"", '1. Halbjahr'!B19, "") | C19: =IF(D19="","",IF($H$3="BE", INDIRECT("P"&MATCH(M19-0.001,$Q$4:$Q$20,-1)+4),D19)) | F19: 3 | G19: =IF(G$25="","",COUNTIF(C$4:C$38,F19)) -> 0 | H19: =IF(G$25="","",G19/G$25) -> #DIV/0! | J19: =+B19&D19 | M19: =IF(D19="","",IF($H$3="BE",100 * D19 / IF(E19="",$H$30,E19))) | O19: =$H$34-0.01 -> 19.99 | P19: 1 | Q19: =(O19-100*SUM($A$43:A57)/$H$30) -> 19.99
A20: 17 | B20: =IF('1. Halbjahr'!B20<>"", '1. Halbjahr'!B20, "") | C20: =IF(D20="","",IF($H$3="BE", INDIRECT("P"&MATCH(M20-0.001,$Q$4:$Q$20,-1)+4),D20)) | F20: 2 | G20: =IF(G$25="","",COUNTIF(C$4:C$38,F20)) -> 0 | H20: =IF(G$25="","",G20/G$25) -> #DIV/0! | I20: =+H19+H20+H21 -> #DIV/0! | J20: =+B20&D20 | M20: =IF(D20="","",IF($H$3="BE",100 * D20 / IF(E20="",$H$30,E20))) | O20: 0 | P20: 0 | Q20: 0
A21: 18 | B21: =IF('1. Halbjahr'!B21<>"", '1. Halbjahr'!B21, "") | C21: =IF(D21="","",IF($H$3="BE", INDIRECT("P"&MATCH(M21-0.001,$Q$4:$Q$20,-1)+4),D21)) | F21: 1 | G21: =IF(G$25="","",COUNTIF(C$4:C$38,F21)) -> 0 | H21: =IF(G$25="","",G21/G$25) -> #DIV/0! | I21: =+G19+G20+G21 -> 0 | J21: =+B21&D21 | M21: =IF(D21="","",IF($H$3="BE",100 * D21 / IF(E21="",$H$30,E21)))
A22: 19 | B22: =IF('1. Halbjahr'!B22<>"", '1. Halbjahr'!B22, "") | C22: =IF(D22="","",IF($H$3="BE", INDIRECT("P"&MATCH(M22-0.001,$Q$4:$Q$20,-1)+4),D22)) | F22: 0 | G22: =IF(G$25="","",COUNTIF(C$4:C$38,F22)) -> 0 | H22: =IF(G$25="","",G22/G$25) -> #DIV/0! | I22: =+H22 -> #DIV/0! | J22: =+B22&D22 | M22: =IF(D22="","",IF($H$3="BE",100 * D22 / IF(E22="",$H$30,E22)))
A23: 20 | B23: =IF('1. Halbjahr'!B23<>"", '1. Halbjahr'!B23, "") | C23: =IF(D23="","",IF($H$3="BE", INDIRECT("P"&MATCH(M23-0.001,$Q$4:$Q$20,-1)+4),D23)) | F23: Schnitt | G23: =AVERAGE(C4:C38) -> #DIV/0! | H23: =+(17-G23)/3 -> #DIV/0! | I23: =+G22 -> 0 | J23: =+B23&D23 | M23: =IF(D23="","",IF($H$3="BE",100 * D23 / IF(E23="",$H$30,E23)))
A24: 21 | B24: =IF('1. Halbjahr'!B24<>"", '1. Halbjahr'!B24, "") | C24: =IF(D24="","",IF($H$3="BE", INDIRECT("P"&MATCH(M24-0.001,$Q$4:$Q$20,-1)+4),D24)) | J24: =+B24&D24 | M24: =IF(D24="","",IF($H$3="BE",100 * D24 / IF(E24="",$H$30,E24)))
A25: 22 | B25: =IF('1. Halbjahr'!B25<>"", '1. Halbjahr'!B25, "") | C25: =IF(D25="","",IF($H$3="BE", INDIRECT("P"&MATCH(M25-0.001,$Q$4:$Q$20,-1)+4),D25)) | F25: Teiln.: | G25: =COUNT(D4:D38) -> 0 | J25: =+B25&D25 | M25: =IF(D25="","",IF($H$3="BE",100 * D25 / IF(E25="",$H$30,E25)))
A26: 23 | B26: =IF('1. Halbjahr'!B26<>"", '1. Halbjahr'!B26, "") | C26: =IF(D26="","",IF($H$3="BE", INDIRECT("P"&MATCH(M26-0.001,$Q$4:$Q$20,-1)+4),D26)) | F26: Fehlend | G26: =+G27-G25 -> 0 | J26: =+B26&D26 | M26: =IF(D26="","",IF($H$3="BE",100 * D26 / IF(E26="",$H$30,E26)))
A27: 24 | B27: =IF('1. Halbjahr'!B27<>"", '1. Halbjahr'!B27, "") | C27: =IF(D27="","",IF($H$3="BE", INDIRECT("P"&MATCH(M27-0.001,$Q$4:$Q$20,-1)+4),D27)) | F27: Gesamt | G27: =35-COUNTIF(J4:J38,"") -> 0 | J27: =+B27&D27 | M27: =IF(D27="","",IF($H$3="BE",100 * D27 / IF(E27="",$H$30,E27)))
A28: 25 | B28: =IF('1. Halbjahr'!B28<>"", '1. Halbjahr'!B28, "") | C28: =IF(D28="","",IF($H$3="BE", INDIRECT("P"&MATCH(M28-0.001,$Q$4:$Q$20,-1)+4),D28)) | J28: =+B28&D28 | M28: =IF(D28="","",IF($H$3="BE",100 * D28 / IF(E28="",$H$30,E28)))
A29: 26 | B29: =IF('1. Halbjahr'!B29<>"", '1. Halbjahr'!B29, "") | C29: =IF(D29="","",IF($H$3="BE", INDIRECT("P"&MATCH(M29-0.001,$Q$4:$Q$20,-1)+4),D29)) | F29: Bewertungseinheiten gesamt | J29: =+B29&D29 | M29: =IF(D29="","",IF($H$3="BE",100 * D29 / IF(E29="",$H$30,E29)))
A30: 27 | B30: =IF('1. Halbjahr'!B30<>"", '1. Halbjahr'!B30, "") | C30: =IF(D30="","",IF($H$3="BE", INDIRECT("P"&MATCH(M30-0.001,$Q$4:$Q$20,-1)+4),D30)) | H30: 18 | J30: =+B30&D30 | M30: =IF(D30="","",IF($H$3="BE",100 * D30 / IF(E30="",$H$30,E30)))
A31: 28 | B31: =IF('1. Halbjahr'!B31<>"", '1. Halbjahr'!B31, "") | C31: =IF(D31="","",IF($H$3="BE", INDIRECT("P"&MATCH(M31-0.001,$Q$4:$Q$20,-1)+4),D31)) | J31: =+B31&D31 | M31: =IF(D31="","",IF($H$3="BE",100 * D31 / IF(E31="",$H$30,E31)))
A32: 29 | B32: =IF('1. Halbjahr'!B32<>"", '1. Halbjahr'!B32, "") | C32: =IF(D32="","",IF($H$3="BE", INDIRECT("P"&MATCH(M32-0.001,$Q$4:$Q$20,-1)+4),D32)) | F32: Schlüssel | H32: M | J32: =+B32&D32 | M32: =IF(D32="","",IF($H$3="BE",100 * D32 / IF(E32="",$H$30,E32)))
A33: 30 | B33: =IF('1. Halbjahr'!B33<>"", '1. Halbjahr'!B33, "") | C33: =IF(D33="","",IF($H$3="BE", INDIRECT("P"&MATCH(M33-0.001,$Q$4:$Q$20,-1)+4),D33)) | F33: Bereich Note 5 | J33: =+B33&D33 | M33: =IF(D33="","",IF($H$3="BE",100 * D33 / IF(E33="",$H$30,E33)))
A34: 31 | B34: =IF('1. Halbjahr'!B34<>"", '1. Halbjahr'!B34, "") | C34: =IF(D34="","",IF($H$3="BE", INDIRECT("P"&MATCH(M34-0.001,$Q$4:$Q$20,-1)+4),D34)) | F34: von Untergrenze | H34: 20 | I34: % | J34: =+B34&D34 | M34: =IF(D34="","",IF($H$3="BE",100 * D34 / IF(E34="",$H$30,E34)))
A35: 32 | B35: =IF('1. Halbjahr'!B35<>"", '1. Halbjahr'!B35, "") | C35: =IF(D35="","",IF($H$3="BE", INDIRECT("P"&MATCH(M35-0.001,$Q$4:$Q$20,-1)+4),D35)) | F35: bis Obergrenze | H35: 40 | I35: % | J35: =+B35&D35 | M35: =IF(D35="","",IF($H$3="BE",100 * D35 / IF(E35="",$H$30,E35)))
A36: 33 | B36: =IF('1. Halbjahr'!B36<>"", '1. Halbjahr'!B36, "") | C36: =IF(D36="","",IF($H$3="BE", INDIRECT("P"&MATCH(M36-0.001,$Q$4:$Q$20,-1)+4),D36)) | J36: =+B36&D36 | M36: =IF(D36="","",IF($H$3="BE",100 * D36 / IF(E36="",$H$30,E36)))
A37: 34 | B37: =IF('1. Halbjahr'!B37<>"", '1. Halbjahr'!B37, "") | C37: =IF(D37="","",IF($H$3="BE", INDIRECT("P"&MATCH(M37-0.001,$Q$4:$Q$20,-1)+4),D37)) | J37: =+B37&D37 | M37: =IF(D37="","",IF($H$3="BE",100 * D37 / IF(E37="",$H$30,E37)))
A38: 35 | B38: =IF('1. Halbjahr'!B38<>"", '1. Halbjahr'!B38, "") | C38: =IF(D38="","",IF($H$3="BE", INDIRECT("P"&MATCH(M38-0.001,$Q$4:$Q$20,-1)+4),D38)) | J38: =+B38&D38 | M38: =IF(D38="","",IF($H$3="BE",100 * D38 / IF(E38="",$H$30,E38)))
B40: Breite Punkte | C40: Bewertungs- | E40: Kontrolle
B41: angepasst | C41: einheiten | E41: Alarm bei Abweichung
...

Sheet I2KA
B1: I - 2. Kurzarbeit aus | C1: =IF('1. Halbjahr'!E1="","",'1. Halbjahr'!E1) | F1: Datum:
B2: Klasse: | C2: =IF('1. Halbjahr'!B1="","",'1. Halbjahr'!B1) | F2: Lehrer/-in: | G2: =IF('1. Halbjahr'!K1="","",'1. Halbjahr'!K1)
A3: Nr | B3: Name | C3: Punkte | D3: =IF(H3="BE",H3,"") -> BE | E3: NT | G3: Eingabe über: | H3: BE | M3: Prozentsatz erreicht | O3: Notenschluessel | Q3: modifiziert
A4: 1 | B4: =IF('1. Halbjahr'!B4<>"", '1. Halbjahr'!B4, "") | C4: =IF(D4="","",IF($H$3="BE", INDIRECT("P"&MATCH(M4-0.001,$Q$4:$Q$20,-1)+4),D4)) | J4: =+B4&D4 | M4: =IF(D4="","",IF($H$3="BE",100 * D4 / IF(E4="",$H$30,E4))) | O4: =IF($H$32="M", $H$35+12*(100-$H$35)/12, $H$35+30*(100-$H$35)/30) -> 100 | Q4: 100
A5: 2 | B5: =IF('1. Halbjahr'!B5<>"", '1. Halbjahr'!B5, "") | C5: =IF(D5="","",IF($H$3="BE", INDIRECT("P"&MATCH(M5-0.001,$Q$4:$Q$20,-1)+4),D5)) | F5: Auswertung | J5: =+B5&D5 | M5: =IF(D5="","",IF($H$3="BE",100 * D5 / IF(E5="",$H$30,E5))) | O5: =IF($H$32="M", $H$35+11*(100-$H$35)/12, $H$35+27*(100-$H$35)/30) -> 95 | P5: 15 | Q5: =(O5-100*SUM($A$43:A43)/$H$30) -> 95
A6: 3 | B6: =IF('1. Halbjahr'!B6<>"", '1. Halbjahr'!B6, "") | C6: =IF(D6="","",IF($H$3="BE", INDIRECT("P"&MATCH(M6-0.001,$Q$4:$Q$20,-1)+4),D6)) | F6: Punkte | G6: Anzahl | H6: Anteil | J6: =+B6&D6 | M6: =IF(D6="","",IF($H$3="BE",100 * D6 / IF(E6="",$H$30,E6))) | O6: =IF($H$32="M", $H$35+10*(100-$H$35)/12, $H$35+24*(100-$H$35)/30) -> 90 | P6: 14 | Q6: =(O6-100*SUM($A$43:A44)/$H$30) -> 90
A7: 4 | B7: =IF('1. Halbjahr'!B7<>"", '1. Halbjahr'!B7, "") | C7: =IF(D7="","",IF($H$3="BE", INDIRECT("P"&MATCH(M7-0.001,$Q$4:$Q$20,-1)+4),D7)) | F7: 15 | G7: =IF(G$25="","",COUNTIF(C$4:C$38,F7)) -> 0 | H7: =IF(G$25="","",G7/G$25) -> #DIV/0! | J7: =+B7&D7 | M7: =IF(D7="","",IF($H$3="BE",100 * D7 / IF(E7="",$H$30,E7))) | O7: =IF($H$32="M", $H$35+9*(100-$H$35)/12, $H$35+21*(100-$H$35)/30) -> 85 | P7: 13 | Q7: =(O7-100*SUM($A$43:A45)/$H$30) -> 85
A8: 5 | B8: =IF('1. Halbjahr'!B8<>"", '1. Halbjahr'!B8, "") | C8: =IF(D8="","",IF($H$3="BE", INDIRECT("P"&MATCH(M8-0.001,$Q$4:$Q$20,-1)+4),D8)) | F8: 14 | G8: =IF(G$25="","",COUNTIF(C$4:C$38,F8)) -> 0 | H8: =IF(G$25="","",G8/G$25) -> #DIV/0! | I8: =+H7+H8+H9 -> #DIV/0! | J8: =+B8&D8 | M8: =IF(D8="","",IF($H$3="BE",100 * D8 / IF(E8="",$H$30,E8))) | O8: =IF($H$32="M", $H$35+8*(100-$H$35)/12, $H$35+18*(100-$H$35)/30) -> 80 | P8: 12 | Q8: =(O8-100*SUM($A$43:A46)/$H$30) -> 80
A9: 6 | B9: =IF('1. Halbjahr'!B9<>"", '1. Halbjahr'!B9, "") | C9: =IF(D9="","",IF($H$3="BE", INDIRECT("P"&MATCH(M9-0.001,$Q$4:$Q$20,-1)+4),D9)) | F9: 13 | G9: =IF(G$25="","",COUNTIF(C$4:C$38,F9)) -> 0 | H9: =IF(G$25="","",G9/G$25) -> #DIV/0! | I9: =+G7+G8+G9 -> 0 | J9: =+B9&D9 | M9: =IF(D9="","",IF($H$3="BE",100 * D9 / IF(E9="",$H$30,E9))) | O9: =IF($H$32="M", $H$35+7*(100-$H$35)/12, $H$35+15*(100-$H$35)/30) -> 75 | P9: 11 | Q9: =(O9-100*SUM($A$43:A47)/$H$30) -> 75
A10: 7 | B10: =IF('1. Halbjahr'!B10<>"", '1. Halbjahr'!B10, "") | C10: =IF(D10="","",IF($H$3="BE", INDIRECT("P"&MATCH(M10-0.001,$Q$4:$Q$20,-1)+4),D10)) | F10: 12 | G10: =IF(G$25="","",COUNTIF(C$4:C$38,F10)) -> 0 | H10: =IF(G$25="","",G10/G$25) -> #DIV/0! | J10: =+B10&D10 | M10: =IF(D10="","",IF($H$3="BE",100 * D10 / IF(E10="",$H$30,E10))) | O10: =IF($H$32="M", $H$35+6*(100-$H$35)/12, $H$35+12*(100-$H$35)/30) -> 70 | P10: 10 | Q10: =(O10-100*SUM($A$43:A48)/$H$30) -> 70
A11: 8 | B11: =IF('1. Halbjahr'!B11<>"", '1. Halbjahr'!B11, "") | C11: =IF(D11="","",IF($H$3="BE", INDIRECT("P"&MATCH(M11-0.001,$Q$4:$Q$20,-1)+4),D11)) | F11: 11 | G11: =IF(G$25="","",COUNTIF(C$4:C$38,F11)) -> 0 | H11: =IF(G$25="","",G11/G$25) -> #DIV/0! | I11: =+H10+H11+H12 -> #DIV/0! | J11: =+B11&D11 | M11: =IF(D11="","",IF($H$3="BE",100 * D11 / IF(E11="",$H$30,E11))) | O11: =IF($H$32="M", $H$35+5*(100-$H$35)/12, $H$35+10*(100-$H$35)/30) -> 65 | P11: 9 | Q11: =(O11-100*SUM($A$43:A49)/$H$30) -> 65
A12: 9 | B12: =IF('1. Halbjahr'!B12<>"", '1. Halbjahr'!B12, "") | C12: =IF(D12="","",IF($H$3="BE", INDIRECT("P"&MATCH(M12-0.001,$Q$4:$Q$20,-1)+4),D12)) | F12: 10 | G12: =IF(G$25="","",COUNTIF(C$4:C$38,F12)) -> 0 | H12: =IF(G$25="","",G12/G$25) -> #DIV/0! | I12: =+G10+G11+G12 -> 0 | J12: =+B12&D12 | M12: =IF(D12="","",IF($H$3="BE",100 * D12 / IF(E12="",$H$30,E12))) | O12: =IF($H$32="M", $H$35+4*(100-$H$35)/12, $H$35+8*(100-$H$35)/30) -> 60 | P12: 8 | Q12: =(O12-100*SUM($A$43:A50)/$H$30) -> 60
A13: 10 | B13: =IF('1. Halbjahr'!B13<>"", '1. Halbjahr'!B13, "") | C13: =IF(D13="","",IF($H$3="BE", INDIRECT("P"&MATCH(M13-0.001,$Q$4:$Q$20,-1)+4),D13)) | F13: 9 | G13: =IF(G$25="","",COUNTIF(C$4:C$38,F13)) -> 0 | H13: =IF(G$25="","",G13/G$25) -> #DIV/0! | J13: =+B13&D13 | M13: =IF(D13="","",IF($H$3="BE",100 * D13 / IF(E13="",$H$30,E13))) | O13: =IF($H$32="M", $H$35+3*(100-$H$35)/12, $H$35+6*(100-$H$35)/30) -> 55 | P13: 7 | Q13: =(O13-100*SUM($A$43:A51)/$H$30) -> 55
A14: 11 | B14: =IF('1. Halbjahr'!B14<>"", '1. Halbjahr'!B14, "") | C14: =IF(D14="","",IF($H$3="BE", INDIRECT("P"&MATCH(M14-0.001,$Q$4:$Q$20,-1)+4),D14)) | F14: 8 | G14: =IF(G$25="","",COUNTIF(C$4:C$38,F14)) -> 0 | H14: =IF(G$25="","",G14/G$25) -> #DIV/0! | I14: =+H13+H14+H15 -> #DIV/0! | J14: =+B14&D14 | M14: =IF(D14="","",IF($H$3="BE",100 * D14 / IF(E14="",$H$30,E14))) | O14: =IF($H$32="M", $H$35+2*(100-$H$35)/12, $H$35+4*(100-$H$35)/30) -> 50 | P14: 6 | Q14: =(O14-100*SUM($A$43:A52)/$H$30) -> 50
A15: 12 | B15: =IF('1. Halbjahr'!B15<>"", '1. Halbjahr'!B15, "") | C15: =IF(D15="","",IF($H$3="BE", INDIRECT("P"&MATCH(M15-0.001,$Q$4:$Q$20,-1)+4),D15)) | F15: 7 | G15: =IF(G$25="","",COUNTIF(C$4:C$38,F15)) -> 0 | H15: =IF(G$25="","",G15/G$25) -> #DIV/0! | I15: =+G13+G14+G15 -> 0 | J15: =+B15&D15 | M15: =IF(D15="","",IF($H$3="BE",100 * D15 / IF(E15="",$H$30,E15))) | O15: =IF($H$32="M", $H$35+1*(100-$H$35)/12, $H$35+2*(100-$H$35)/30) -> 45 | P15: 5 | Q15: =(O15-100*SUM($A$43:A53)/$H$30) -> 45
A16: 13 | B16: =IF('1. Halbjahr'!B16<>"", '1. Halbjahr'!B16, "") | C16: =IF(D16="","",IF($H$3="BE", INDIRECT("P"&MATCH(M16-0.001,$Q$4:$Q$20,-1)+4),D16)) | F16: 6 | G16: =IF(G$25="","",COUNTIF(C$4:C$38,F16)) -> 0 | H16: =IF(G$25="","",G16/G$25) -> #DIV/0! | J16: =+B16&D16 | M16: =IF(D16="","",IF($H$3="BE",100 * D16 / IF(E16="",$H$30,E16))) | O16: =$H$35 -> 40 | P16: 4 | Q16: =(O16-100*SUM($A$43:A54)/$H$30) -> 40
A17: 14 | B17: =IF('1. Halbjahr'!B17<>"", '1. Halbjahr'!B17, "") | C17: =IF(D17="","",IF($H$3="BE", INDIRECT("P"&MATCH(M17-0.001,$Q$4:$Q$20,-1)+4),D17)) | F17: 5 | G17: =IF(G$25="","",COUNTIF(C$4:C$38,F17)) -> 0 | H17: =IF(G$25="","",G17/G$25) -> #DIV/0! | I17: =+H16+H17+H18 -> #DIV/0! | J17: =+B17&D17 | M17: =IF(D17="","",IF($H$3="BE",100 * D17 / IF(E17="",$H$30,E17))) | O17: =($H$34+2*($H$35-$H$34)/3) -> 33.333333 | P17: 3 | Q17: =(O17-100*SUM($A$43:A55)/$H$30) -> 33.333333
A18: 15 | B18: =IF('1. Halbjahr'!B18<>"", '1. Halbjahr'!B18, "") | C18: =IF(D18="","",IF($H$3="BE", INDIRECT("P"&MATCH(M18-0.001,$Q$4:$Q$20,-1)+4),D18)) | F18: 4 | G18: =IF(G$25="","",COUNTIF(C$4:C$38,F18)) -> 0 | H18: =IF(G$25="","",G18/G$25) -> #DIV/0! | I18: =+G16+G17+G18 -> 0 | J18: =+B18&D18 | M18: =IF(D18="","",IF($H$3="BE",100 * D18 / IF(E18="",$H$30,E18))) | O18: =($H$34+($H$35-$H$34)/3) -> 26.666667 | P18: 2 | Q18: =(O18-100*SUM($A$43:A56)/$H$30) -> 26.666667
A19: 16 | B19: =IF('1. Halbjahr'!B19<>"", '1. Halbjahr'!B19, "") | C19: =IF(D19="","",IF($H$3="BE", INDIRECT("P"&MATCH(M19-0.001,$Q$4:$Q$20,-1)+4),D19)) | F19: 3 | G19: =IF(G$25="","",COUNTIF(C$4:C$38,F19)) -> 0 | H19: =IF(G$25="","",G19/G$25) -> #DIV/0! | J19: =+B19&D19 | M19: =IF(D19="","",IF($H$3="BE",100 * D19 / IF(E19="",$H$30,E19))) | O19: =$H$34-0.01 -> 19.99 | P19: 1 | Q19: =(O19-100*SUM($A$43:A57)/$H$30) -> 19.99
A20: 17 | B20: =IF('1. Halbjahr'!B20<>"", '1. Halbjahr'!B20, "") | C20: =IF(D20="","",IF($H$3="BE", INDIRECT("P"&MATCH(M20-0.001,$Q$4:$Q$20,-1)+4),D20)) | F20: 2 | G20: =IF(G$25="","",COUNTIF(C$4:C$38,F20)) -> 0 | H20: =IF(G$25="","",G20/G$25) -> #DIV/0! | I20: =+H19+H20+H21 -> #DIV/0! | J20: =+B20&D20 | M20: =IF(D20="","",IF($H$3="BE",100 * D20 / IF(E20="",$H$30,E20))) | O20: 0 | P20: 0 | Q20: 0
A21: 18 | B21: =IF('1. Halbjahr'!B21<>"", '1. Halbjahr'!B21, "") | C21: =IF(D21="","",IF($H$3="BE", INDIRECT("P"&MATCH(M21-0.001,$Q$4:$Q$20,-1)+4),D21)) | F21: 1 | G21: =IF(G$25="","",COUNTIF(C$4:C$38,F21)) -> 0 | H21: =IF(G$25="","",G21/G$25) -> #DIV/0! | I21: =+G19+G20+G21 -> 0 | J21: =+B21&D21 | M21: =IF(D21="","",IF($H$3="BE",100 * D21 / IF(E21="",$H$30,E21)))
A22: 19 | B22: =IF('1. Halbjahr'!B22<>"", '1. Halbjahr'!B22, "") | C22: =IF(D22="","",IF($H$3="BE", INDIRECT("P"&MATCH(M22-0.001,$Q$4:$Q$20,-1)+4),D22)) | F22: 0 | G22: =IF(G$25="","",COUNTIF(C$4:C$38,F22)) -> 0 | H22: =IF(G$25="","",G22/G$25) -> #DIV/0! | I22: =+H22 -> #DIV/0! | J22: =+B22&D22 | M22: =IF(D22="","",IF($H$3="BE",100 * D22 / IF(E22="",$H$30,E22)))
A23: 20 | B23: =IF('1. Halbjahr'!B23<>"", '1. Halbjahr'!B23, "") | C23: =IF(D23="","",IF($H$3="BE", INDIRECT("P"&MATCH(M23-0.001,$Q$4:$Q$20,-1)+4),D23)) | F23: Schnitt | G23: =AVERAGE(C4:C38) -> #DIV/0! | H23: =+(17-G23)/3 -> #DIV/0! | I23: =+G22 -> 0 | J23: =+B23&D23 | M23: =IF(D23="","",IF($H$3="BE",100 * D23 / IF(E23="",$H$30,E23)))
A24: 21 | B24: =IF('1. Halbjahr'!B24<>"", '1. Halbjahr'!B24, "") | C24: =IF(D24="","",IF($H$3="BE", INDIRECT("P"&MATCH(M24-0.001,$Q$4:$Q$20,-1)+4),D24)) | J24: =+B24&D24 | M24: =IF(D24="","",IF($H$3="BE",100 * D24 / IF(E24="",$H$30,E24)))
A25: 22 | B25: =IF('1. Halbjahr'!B25<>"", '1. Halbjahr'!B25, "") | C25: =IF(D25="","",IF($H$3="BE", INDIRECT("P"&MATCH(M25-0.001,$Q$4:$Q$20,-1)+4),D25)) | F25: Teiln.: | G25: =COUNT(D4:D38) -> 0 | J25: =+B25&D25 | M25: =IF(D25="","",IF($H$3="BE",100 * D25 / IF(E25="",$H$30,E25)))
A26: 23 | B26: =IF('1. Halbjahr'!B26<>"", '1. Halbjahr'!B26, "") | C26: =IF(D26="","",IF($H$3="BE", INDIRECT("P"&MATCH(M26-0.001,$Q$4:$Q$20,-1)+4),D26)) | F26: Fehlend | G26: =+G27-G25 -> 0 | J26: =+B26&D26 | M26: =IF(D26="","",IF($H$3="BE",100 * D26 / IF(E26="",$H$30,E26)))
A27: 24 | B27: =IF('1. Halbjahr'!B27<>"", '1. Halbjahr'!B27, "") | C27: =IF(D27="","",IF($H$3="BE", INDIRECT("P"&MATCH(M27-0.001,$Q$4:$Q$20,-1)+4),D27)) | F27: Gesamt | G27: =35-COUNTIF(J4:J38,"") -> 0 | J27: =+B27&D27 | M27: =IF(D27="","",IF($H$3="BE",100 * D27 / IF(E27="",$H$30,E27)))
A28: 25 | B28: =IF('1. Halbjahr'!B28<>"", '1. Halbjahr'!B28, "") | C28: =IF(D28="","",IF($H$3="BE", INDIRECT("P"&MATCH(M28-0.001,$Q$4:$Q$20,-1)+4),D28)) | J28: =+B28&D28 | M28: =IF(D28="","",IF($H$3="BE",100 * D28 / IF(E28="",$H$30,E28)))
A29: 26 | B29: =IF('1. Halbjahr'!B29<>"", '1. Halbjahr'!B29, "") | C29: =IF(D29="","",IF($H$3="BE", INDIRECT("P"&MATCH(M29-0.001,$Q$4:$Q$20,-1)+4),D29)) | F29: Bewertungseinheiten gesamt | J29: =+B29&D29 | M29: =IF(D29="","",IF($H$3="BE",100 * D29 / IF(E29="",$H$30,E29)))
A30: 27 | B30: =IF('1. Halbjahr'!B30<>"", '1. Halbjahr'!B30, "") | C30: =IF(D30="","",IF($H$3="BE", INDIRECT("P"&MATCH(M30-0.001,$Q$4:$Q$20,-1)+4),D30)) | H30: 18 | J30: =+B30&D30 | M30: =IF(D30="","",IF($H$3="BE",100 * D30 / IF(E30="",$H$30,E30)))
A31: 28 | B31: =IF('1. Halbjahr'!B31<>"", '1. Halbjahr'!B31, "") | C31: =IF(D31="","",IF($H$3="BE", INDIRECT("P"&MATCH(M31-0.001,$Q$4:$Q$20,-1)+4),D31)) | J31: =+B31&D31 | M31: =IF(D31="","",IF($H$3="BE",100 * D31 / IF(E31="",$H$30,E31)))
A32: 29 | B32: =IF('1. Halbjahr'!B32<>"", '1. Halbjahr'!B32, "") | C32: =IF(D32="","",IF($H$3="BE", INDIRECT("P"&MATCH(M32-0.001,$Q$4:$Q$20,-1)+4),D32)) | F32: Schlüssel | H32: M | J32: =+B32&D32 | M32: =IF(D32="","",IF($H$3="BE",100 * D32 / IF(E32="",$H$30,E32)))
A33: 30 | B33: =IF('1. Halbjahr'!B33<>"", '1. Halbjahr'!B33, "") | C33: =IF(D33="","",IF($H$3="BE", INDIRECT("P"&MATCH(M33-0.001,$Q$4:$Q$20,-1)+4),D33)) | F33: Bereich Note 5 | J33: =+B33&D33 | M33: =IF(D33="","",IF($H$3="BE",100 * D33 / IF(E33="",$H$30,E33)))
A34: 31 | B34: =IF('1. Halbjahr'!B34<>"", '1. Halbjahr'!B34, "") | C34: =IF(D34="","",IF($H$3="BE", INDIRECT("P"&MATCH(M34-0.001,$Q$4:$Q$20,-1)+4),D34)) | F34: von Untergrenze | H34: 20 | I34: % | J34: =+B34&D34 | M34: =IF(D34="","",IF($H$3="BE",100 * D34 / IF(E34="",$H$30,E34)))
A35: 32 | B35: =IF('1. Halbjahr'!B35<>"", '1. Halbjahr'!B35, "") | C35: =IF(D35="","",IF($H$3="BE", INDIRECT("P"&MATCH(M35-0.001,$Q$4:$Q$20,-1)+4),D35)) | F35: bis Obergrenze | H35: 40 | I35: % | J35: =+B35&D35 | M35: =IF(D35="","",IF($H$3="BE",100 * D35 / IF(E35="",$H$30,E35)))
A36: 33 | B36: =IF('1. Halbjahr'!B36<>"", '1. Halbjahr'!B36, "") | C36: =IF(D36="","",IF($H$3="BE", INDIRECT("P"&MATCH(M36-0.001,$Q$4:$Q$20,-1)+4),D36)) | J36: =+B36&D36 | M36: =IF(D36="","",IF($H$3="BE",100 * D36 / IF(E36="",$H$30,E36)))
A37: 34 | B37: =IF('1. Halbjahr'!B37<>"", '1. Halbjahr'!B37, "") | C37: =IF(D37="","",IF($H$3="BE", INDIRECT("P"&MATCH(M37-0.001,$Q$4:$Q$20,-1)+4),D37)) | J37: =+B37&D37 | M37: =IF(D37="","",IF($H$3="BE",100 * D37 / IF(E37="",$H$30,E37)))
A38: 35 | B38: =IF('1. Halbjahr'!B38<>"", '1. Halbjahr'!B38, "") | C38: =IF(D38="","",IF($H$3="BE", INDIRECT("P"&MATCH(M38-0.001,$Q$4:$Q$20,-1)+4),D38)) | J38: =+B38&D38 | M38: =IF(D38="","",IF($H$3="BE",100 * D38 / IF(E38="",$H$30,E38)))
B40: Breite Punkte | C40: Bewertungs- | E40: Kontrolle
B41: angepasst | C41: einheiten | E41: Alarm bei Abweichung
...

Sheet I1Ext
B1: I - 1. Stegreifaufgabe aus | C1: =IF('1. Halbjahr'!E1="","",'1. Halbjahr'!E1) | F1: Datum:
B2: Klasse: | C2: =IF('1. Halbjahr'!B1="","",'1. Halbjahr'!B1) | F2: Lehrer/-in: | G2: =IF('1. Halbjahr'!K1="","",'1. Halbjahr'!K1)
A3: Nr | B3: Name | C3: Punkte | D3: =IF(H3="BE",H3,"") -> BE | E3: NT | G3: Eingabe über: | H3: BE | M3: Prozentsatz erreicht | O3: Notenschluessel | Q3: modifiziert
A4: 1 | B4: =IF('1. Halbjahr'!B4<>"", '1. Halbjahr'!B4, "") | C4: =IF(D4="","",IF($H$3="BE", INDIRECT("P"&MATCH(M4-0.001,$Q$4:$Q$20,-1)+4),D4)) | J4: =+B4&D4 | M4: =IF(D4="","",IF($H$3="BE",100 * D4 / IF(E4="",$H$30,E4))) | O4: =IF($H$32="M", $H$35+12*(100-$H$35)/12, $H$35+30*(100-$H$35)/30) -> 100 | Q4: 100
A5: 2 | B5: =IF('1. Halbjahr'!B5<>"", '1. Halbjahr'!B5, "") | C5: =IF(D5="","",IF($H$3="BE", INDIRECT("P"&MATCH(M5-0.001,$Q$4:$Q$20,-1)+4),D5)) | F5: Auswertung | J5: =+B5&D5 | M5: =IF(D5="","",IF($H$3="BE",100 * D5 / IF(E5="",$H$30,E5))) | O5: =IF($H$32="M", $H$35+11*(100-$H$35)/12, $H$35+27*(100-$H$35)/30) -> 95 | P5: 15 | Q5: =(O5-100*SUM($A$43:A43)/$H$30) -> 95
A6: 3 | B6: =IF('1. Halbjahr'!B6<>"", '1. Halbjahr'!B6, "") | C6: =IF(D6="","",IF($H$3="BE", INDIRECT("P"&MATCH(M6-0.001,$Q$4:$Q$20,-1)+4),D6)) | F6: Punkte | G6: Anzahl | H6: Anteil | J6: =+B6&D6 | M6: =IF(D6="","",IF($H$3="BE",100 * D6 / IF(E6="",$H$30,E6))) | O6: =IF($H$32="M", $H$35+10*(100-$H$35)/12, $H$35+24*(100-$H$35)/30) -> 90 | P6: 14 | Q6: =(O6-100*SUM($A$43:A44)/$H$30) -> 90
A7: 4 | B7: =IF('1. Halbjahr'!B7<>"", '1. Halbjahr'!B7, "") | C7: =IF(D7="","",IF($H$3="BE", INDIRECT("P"&MATCH(M7-0.001,$Q$4:$Q$20,-1)+4),D7)) | F7: 15 | G7: =IF(G$25="","",COUNTIF(C$4:C$38,F7)) -> 0 | H7: =IF(G$25="","",G7/G$25) -> #DIV/0! | J7: =+B7&D7 | M7: =IF(D7="","",IF($H$3="BE",100 * D7 / IF(E7="",$H$30,E7))) | O7: =IF($H$32="M", $H$35+9*(100-$H$35)/12, $H$35+21*(100-$H$35)/30) -> 85 | P7: 13 | Q7: =(O7-100*SUM($A$43:A45)/$H$30) -> 85
A8: 5 | B8: =IF('1. Halbjahr'!B8<>"", '1. Halbjahr'!B8, "") | C8: =IF(D8="","",IF($H$3="BE", INDIRECT("P"&MATCH(M8-0.001,$Q$4:$Q$20,-1)+4),D8)) | F8: 14 | G8: =IF(G$25="","",COUNTIF(C$4:C$38,F8)) -> 0 | H8: =IF(G$25="","",G8/G$25) -> #DIV/0! | I8: =+H7+H8+H9 -> #DIV/0! | J8: =+B8&D8 | M8: =IF(D8="","",IF($H$3="BE",100 * D8 / IF(E8="",$H$30,E8))) | O8: =IF($H$32="M", $H$35+8*(100-$H$35)/12, $H$35+18*(100-$H$35)/30) -> 80 | P8: 12 | Q8: =(O8-100*SUM($A$43:A46)/$H$30) -> 80
A9: 6 | B9: =IF('1. Halbjahr'!B9<>"", '1. Halbjahr'!B9, "") | C9: =IF(D9="","",IF($H$3="BE", INDIRECT("P"&MATCH(M9-0.001,$Q$4:$Q$20,-1)+4),D9)) | F9: 13 | G9: =IF(G$25="","",COUNTIF(C$4:C$38,F9)) -> 0 | H9: =IF(G$25="","",G9/G$25) -> #DIV/0! | I9: =+G7+G8+G9 -> 0 | J9: =+B9&D9 | M9: =IF(D9="","",IF($H$3="BE",100 * D9 / IF(E9="",$H$30,E9))) | O9: =IF($H$32="M", $H$35+7*(100-$H$35)/12, $H$35+15*(100-$H$35)/30) -> 75 | P9: 11 | Q9: =(O9-100*SUM($A$43:A47)/$H$30) -> 75
